Workbook

Sheet Kangatang

Sheet 总计
A1: 单价 | B1: 日期 品名 | C1: 1 | D1: 2 | E1: 3 | F1: 4 | G1: 5 | H1: 6 | I1: 7 | J1: 8 | K1: 9 | L1: 10 | M1: 11 | N1: 12 | O1: 13 | P1: 14 | Q1: 15 | R1: 16 | S1: 17 | T1: 18 | U1: 19 | V1: 20 | W1: 21 | X1: 22 | Y1: 23 | Z1: 24 | AA1: 25 | AB1: 26 | AC1: 27 | AD1: 28 | AE1: 29 | AF1: 30 | AG1: 31 | AH1: 总计 | AI1: 总金额
A2: 60 | B2: 圣培露 | C2: ='1'!AX4 -> 0 | D2: ='2'!AX4 -> 0 | E2: ='3'!AX4 -> 0 | F2: ='4'!AX4 -> 0 | G2: ='5'!AX4 -> 0 | H2: ='6'!AX4 -> 0 | I2: ='7'!AX4 -> 0 | J2: ='8'!AX4 -> 0 | K2: ='9'!AX4 -> 0 | L2: ='10'!AX4 -> 0 | M2: ='11'!AX4 -> 0 | N2: ='12'!AX4 -> 0 | O2: ='13'!AX4 -> 0 | P2: ='14'!AX4 -> 0 | Q2: ='15'!AX4 -> 0 | R2: ='16'!AX4 -> 0 | S2: ='17'!AX4 -> 0 | T2: ='18'!AX4 -> 0 | U2: ='19'!AX4 -> 0 | V2: ='20'!AX4 -> 0 | W2: ='21'!AX4 -> 0 | X2: ='22'!AX4 -> 0 | Y2: ='23'!AX4 -> 0 | Z2: ='24'!AX4 -> 0 | AA2: ='25'!AX4 -> 0 | AB2: ='26'!AX4 -> 0 | AC2: ='27'!AX4 -> 0 | AD2: ='28'!AX4 -> 0 | AE2: ='29'!AX4 -> 0 | AF2: ='30'!AX4 -> 0 | AG2: ='31'!AX4 -> 0 | AH2: =SUM(C2:AG2) -> 0 | AI2: =AH2*A2 -> 0
A3: 60 | B3: 芙丝气泡水 | C3: ='1'!AX5 -> 0 | D3: ='2'!AX5 -> 0 | E3: ='3'!AX5 -> 0 | F3: ='4'!AX5 -> 0 | G3: ='5'!AX5 -> 0 | H3: ='6'!AX5 -> 0 | I3: ='7'!AX5 -> 0 | J3: ='8'!AX5 -> 0 | K3: ='9'!AX5 -> 0 | L3: ='10'!AX5 -> 0 | M3: ='11'!AX5 -> 0 | N3: ='12'!AX5 -> 0 | O3: ='13'!AX5 -> 0 | P3: ='14'!AX5 -> 0 | Q3: ='15'!AX5 -> 0 | R3: ='16'!AX5 -> 0 | S3: ='17'!AX5 -> 0 | T3: ='18'!AX5 -> 0 | U3: ='19'!AX5 -> 0 | V3: ='20'!AX5 -> 0 | W3: ='21'!AX5 -> 0 | X3: ='22'!AX5 -> 0 | Y3: ='23'!AX5 -> 0 | Z3: ='24'!AX5 -> 0 | AA3: ='25'!AX5 -> 0 | AB3: ='26'!AX5 -> 0 | AC3: ='27'!AX5 -> 0 | AD3: ='28'!AX5 -> 0 | AE3: ='29'!AX5 -> 0 | AF3: ='30'!AX5 -> 0 | AG3: ='31'!AX5 -> 0 | AH3: =SUM(C3:AG3) -> 0 | AI3: =AH3*A3 -> 0
A4: 38 | B4: 椰子水 | C4: ='1'!AX6 -> 0 | D4: ='2'!AX6 -> 0 | E4: ='3'!AX6 -> 0 | F4: ='4'!AX6 -> 0 | G4: ='5'!AX6 -> 0 | H4: ='6'!AX6 -> 0 | I4: ='7'!AX6 -> 0 | J4: ='8'!AX6 -> 0 | K4: ='9'!AX6 -> 0 | L4: ='10'!AX6 -> 0 | M4: ='11'!AX6 -> 0 | N4: ='12'!AX6 -> 0 | O4: ='13'!AX6 -> 0 | P4: ='14'!AX6 -> 0 | Q4: ='15'!AX6 -> 0 | R4: ='16'!AX6 -> 0 | S4: ='17'!AX6 -> 0 | T4: ='18'!AX6 -> 0 | U4: ='19'!AX6 -> 0 | V4: ='20'!AX6 -> 0 | W4: ='21'!AX6 -> 0 | X4: ='22'!AX6 -> 0 | Y4: ='23'!AX6 -> 0 | Z4: ='24'!AX6 -> 0 | AA4: ='25'!AX6 -> 0 | AB4: ='26'!AX6 -> 0 | AC4: ='27'!AX6 -> 0 | AD4: ='28'!AX6 -> 0 | AE4: ='29'!AX6 -> 0 | AF4: ='30'!AX6 -> 0 | AG4: ='31'!AX6 -> 0 | AH4: =SUM(C4:AG4) -> 0 | AI4: =AH4*A4 -> 0
A5: 38 | B5: 梅子汁 | C5: ='1'!AX7 -> 0 | D5: ='2'!AX7 -> 0 | E5: ='3'!AX7 -> 0 | F5: ='4'!AX7 -> 0 | G5: ='5'!AX7 -> 0 | H5: ='6'!AX7 -> 0 | I5: ='7'!AX7 -> 0 | J5: ='8'!AX7 -> 0 | K5: ='9'!AX7 -> 0 | L5: ='10'!AX7 -> 0 | M5: ='11'!AX7 -> 0 | N5: ='12'!AX7 -> 0 | O5: ='13'!AX7 -> 0 | P5: ='14'!AX7 -> 0 | Q5: ='15'!AX7 -> 0 | R5: ='16'!AX7 -> 0 | S5: ='17'!AX7 -> 0 | T5: ='18'!AX7 -> 0 | U5: ='19'!AX7 -> 0 | V5: ='20'!AX7 -> 0 | W5: ='21'!AX7 -> 0 | X5: ='22'!AX7 -> 0 | Y5: ='23'!AX7 -> 0 | Z5: ='24'!AX7 -> 0 | AA5: ='25'!AX7 -> 0 | AB5: ='26'!AX7 -> 0 | AC5: ='27'!AX7 -> 0 | AD5: ='28'!AX7 -> 0 | AE5: ='29'!AX7 -> 0 | AF5: ='30'!AX7 -> 0 | AG5: ='31'!AX7 -> 0 | AH5: =SUM(C5:AG5) -> 0 | AI5: =AH5*A5 -> 0
A6: 38 | B6: 百事可乐 | C6: ='1'!AX8 -> 0 | D6: ='2'!AX8 -> 0 | E6: ='3'!AX8 -> 0 | F6: ='4'!AX8 -> 0 | G6: ='5'!AX8 -> 0 | H6: ='6'!AX8 -> 0 | I6: ='7'!AX8 -> 0 | J6: ='8'!AX8 -> 0 | K6: ='9'!AX8 -> 0 | L6: ='10'!AX8 -> 0 | M6: ='11'!AX8 -> 0 | N6: ='12'!AX8 -> 0 | O6: ='13'!AX8 -> 0 | P6: ='14'!AX8 -> 0 | Q6: ='15'!AX8 -> 0 | R6: ='16'!AX8 -> 0 | S6: ='17'!AX8 -> 0 | T6: ='18'!AX8 -> 0 | U6: ='19'!AX8 -> 0 | V6: ='20'!AX8 -> 0 | W6: ='21'!AX8 -> 0 | X6: ='22'!AX8 -> 0 | Y6: ='23'!AX8 -> 0 | Z6: ='24'!AX8 -> 0 | AA6: ='25'!AX8 -> 0 | AB6: ='26'!AX8 -> 0 | AC6: ='27'!AX8 -> 0 | AD6: ='28'!AX8 -> 0 | AE6: ='29'!AX8 -> 0 | AF6: ='30'!AX8 -> 0 | AG6: ='31'!AX8 -> 0 | AH6: =SUM(C6:AG6) -> 0 | AI6: =AH6*A6 -> 0
A7: 38 | B7: 健怡百事可乐 | C7: ='1'!AX9 -> 0 | D7: ='2'!AX9 -> 0 | E7: ='3'!AX9 -> 0 | F7: ='4'!AX9 -> 0 | G7: ='5'!AX9 -> 0 | H7: ='6'!AX9 -> 0 | I7: ='7'!AX9 -> 0 | J7: ='8'!AX9 -> 0 | K7: ='9'!AX9 -> 0 | L7: ='10'!AX9 -> 0 | M7: ='11'!AX9 -> 0 | N7: ='12'!AX9 -> 0 | O7: ='13'!AX9 -> 0 | P7: ='14'!AX9 -> 0 | Q7: ='15'!AX9 -> 0 | R7: ='16'!AX9 -> 0 | S7: ='17'!AX9 -> 0 | T7: ='18'!AX9 -> 0 | U7: ='19'!AX9 -> 0 | V7: ='20'!AX9 -> 0 | W7: ='21'!AX9 -> 0 | X7: ='22'!AX9 -> 0 | Y7: ='23'!AX9 -> 0 | Z7: ='24'!AX9 -> 0 | AA7: ='25'!AX9 -> 0 | AB7: ='26'!AX9 -> 0 | AC7: ='27'!AX9 -> 0 | AD7: ='28'!AX9 -> 0 | AE7: ='29'!AX9 -> 0 | AF7: ='30'!AX9 -> 0 | AG7: ='31'!AX9 -> 0 | AH7: =SUM(C7:AG7) -> 0 | AI7: =AH7*A7 -> 0
A8: 38 | B8: 七喜 | C8: ='1'!AX10 -> 0 | D8: ='2'!AX10 -> 0 | E8: ='3'!AX10 -> 0 | F8: ='4'!AX10 -> 0 | G8: ='5'!AX10 -> 0 | H8: ='6'!AX10 -> 0 | I8: ='7'!AX10 -> 0 | J8: ='8'!AX10 -> 0 | K8: ='9'!AX10 -> 0 | L8: ='10'!AX10 -> 0 | M8: ='11'!AX10 -> 0 | N8: ='12'!AX10 -> 0 | O8: ='13'!AX10 -> 0 | P8: ='14'!AX10 -> 0 | Q8: ='15'!AX10 -> 0 | R8: ='16'!AX10 -> 0 | S8: ='17'!AX10 -> 0 | T8: ='18'!AX10 -> 0 | U8: ='19'!AX10 -> 0 | V8: ='20'!AX10 -> 0 | W8: ='21'!AX10 -> 0 | X8: ='22'!AX10 -> 0 | Y8: ='23'!AX10 -> 0 | Z8: ='24'!AX10 -> 0 | AA8: ='25'!AX10 -> 0 | AB8: ='26'!AX10 -> 0 | AC8: ='27'!AX10 -> 0 | AD8: ='28'!AX10 -> 0 | AE8: ='29'!AX10 -> 0 | AF8: ='30'!AX10 -> 0 | AG8: ='31'!AX10 -> 0 | AH8: =SUM(C8:AG8) -> 0 | AI8: =AH8*A8 -> 0
A9: 38 | B9: 苏打水 | C9: ='1'!AX11 -> 0 | D9: ='2'!AX11 -> 0 | E9: ='3'!AX11 -> 0 | F9: ='4'!AX11 -> 0 | G9: ='5'!AX11 -> 0 | H9: ='6'!AX11 -> 0 | I9: ='7'!AX11 -> 0 | J9: ='8'!AX11 -> 0 | K9: ='9'!AX11 -> 0 | L9: ='10'!AX11 -> 0 | M9: ='11'!AX11 -> 0 | N9: ='12'!AX11 -> 0 | O9: ='13'!AX11 -> 0 | P9: ='14'!AX11 -> 0 | Q9: ='15'!AX11 -> 0 | R9: ='16'!AX11 -> 0 | S9: ='17'!AX11 -> 0 | T9: ='18'!AX11 -> 0 | U9: ='19'!AX11 -> 0 | V9: ='20'!AX11 -> 0 | W9: ='21'!AX11 -> 0 | X9: ='22'!AX11 -> 0 | Y9: ='23'!AX11 -> 0 | Z9: ='24'!AX11 -> 0 | AA9: ='25'!AX11 -> 0 | AB9: ='26'!AX11 -> 0 | AC9: ='27'!AX11 -> 0 | AD9: ='28'!AX11 -> 0 | AE9: ='29'!AX11 -> 0 | AF9: ='30'!AX11 -> 0 | AG9: ='31'!AX11 -> 0 | AH9: =SUM(C9:AG9) -> 0 | AI9: =AH9*A9 -> 0
A10: 38 | B10: 汤力水 | C10: ='1'!AX12 -> 0 | D10: ='2'!AX12 -> 0 | E10: ='3'!AX12 -> 0 | F10: ='4'!AX12 -> 0 | G10: ='5'!AX12 -> 0 | H10: ='6'!AX12 -> 0 | I10: ='7'!AX12 -> 0 | J10: ='8'!AX12 -> 0 | K10: ='9'!AX12 -> 0 | L10: ='10'!AX12 -> 0 | M10: ='11'!AX12 -> 0 | N10: ='12'!AX12 -> 0 | O10: ='13'!AX12 -> 0 | P10: ='14'!AX12 -> 0 | Q10: ='15'!AX12 -> 0 | R10: ='16'!AX12 -> 0 | S10: ='17'!AX12 -> 0 | T10: ='18'!AX12 -> 0 | U10: ='19'!AX12 -> 0 | V10: ='20'!AX12 -> 0 | W10: ='21'!AX12 -> 0 | X10: ='22'!AX12 -> 0 | Y10: ='23'!AX12 -> 0 | Z10: ='24'!AX12 -> 0 | AA10: ='25'!AX12 -> 0 | AB10: ='26'!AX12 -> 0 | AC10: ='27'!AX12 -> 0 | AD10: ='28'!AX12 -> 0 | AE10: ='29'!AX12 -> 0 | AF10: ='30'!AX12 -> 0 | AG10: ='31'!AX12 -> 0 | AH10: =SUM(C10:AG10) -> 0 | AI10: =AH10*A10 -> 0
C11: ='1'!AX13 -> 0 | D11: ='2'!AX13 -> 0 | E11: ='3'!AX13 -> 0 | F11: ='4'!AX13 -> 0 | G11: ='5'!AX13 -> 0 | H11: ='6'!AX13 -> 0 | I11: ='7'!AX13 -> 0 | J11: ='8'!AX13 -> 0 | K11: ='9'!AX13 -> 0 | L11: ='10'!AX13 -> 0 | M11: ='11'!AX13 -> 0 | N11: ='12'!AX13 -> 0 | O11: ='13'!AX13 -> 0 | P11: ='14'!AX13 -> 0 | Q11: ='15'!AX13 -> 0 | R11: ='16'!AX13 -> 0 | S11: ='17'!AX13 -> 0 | T11: ='18'!AX13 -> 0 | U11: ='19'!AX13 -> 0 | V11: ='20'!AX13 -> 0 | W11: ='21'!AX13 -> 0 | X11: ='22'!AX13 -> 0 | Y11: ='23'!AX13 -> 0 | Z11: ='24'!AX13 -> 0 | AA11: ='25'!AX13 -> 0 | AB11: ='26'!AX13 -> 0 | AC11: ='27'!AX13 -> 0 | AD11: ='28'!AX13 -> 0 | AE11: ='29'!AX13 -> 0 | AF11: ='30'!AX13 -> 0 | AG11: ='31'!AX13 -> 0 | AH11: =SUM(C11:AG11) -> 0 | AI11: =AH11*A11 -> 0
A12: 58 | B12: 必富达金酒 | C12: ='1'!AX14 -> 0 | D12: ='2'!AX14 -> 0 | E12: ='3'!AX14 -> 0 | F12: ='4'!AX14 -> 0 | G12: ='5'!AX14 -> 0 | H12: ='6'!AX14 -> 0 | I12: ='7'!AX14 -> 0 | J12: ='8'!AX14 -> 0 | K12: ='9'!AX14 -> 0 | L12: ='10'!AX14 -> 0 | M12: ='11'!AX14 -> 0 | N12: ='12'!AX14 -> 0 | O12: ='13'!AX14 -> 0 | P12: ='14'!AX14 -> 0 | Q12: ='15'!AX14 -> 0 | R12: ='16'!AX14 -> 0 | S12: ='17'!AX14 -> 0 | T12: ='18'!AX14 -> 0 | U12: ='19'!AX14 -> 0 | V12: ='20'!AX14 -> 0 | W12: ='21'!AX14 -> 0 | X12: ='22'!AX14 -> 0 | Y12: ='23'!AX14 -> 0 | Z12: ='24'!AX14 -> 0 | AA12: ='25'!AX14 -> 0 | AB12: ='26'!AX14 -> 0 | AC12: ='27'!AX14 -> 0 | AD12: ='28'!AX14 -> 0 | AE12: ='29'!AX14 -> 0 | AF12: ='30'!AX14 -> 0 | AG12: ='31'!AX14 -> 0 | AH12: =SUM(C12:AG12) -> 0 | AI12: =AH12*A12 -> 0
A13: 58 | B13: 绝对伏特加 | C13: ='1'!AX15 -> 0 | D13: ='2'!AX15 -> 0 | E13: ='3'!AX15 -> 0 | F13: ='4'!AX15 -> 0 | G13: ='5'!AX15 -> 0 | H13: ='6'!AX15 -> 0 | I13: ='7'!AX15 -> 0 | J13: ='8'!AX15 -> 0 | K13: ='9'!AX15 -> 0 | L13: ='10'!AX15 -> 0 | M13: ='11'!AX15 -> 0 | N13: ='12'!AX15 -> 0 | O13: ='13'!AX15 -> 0 | P13: ='14'!AX15 -> 0 | Q13: ='15'!AX15 -> 0 | R13: ='16'!AX15 -> 0 | S13: ='17'!AX15 -> 0 | T13: ='18'!AX15 -> 0 | U13: ='19'!AX15 -> 0 | V13: ='20'!AX15 -> 0 | W13: ='21'!AX15 -> 0 | X13: ='22'!AX15 -> 0 | Y13: ='23'!AX15 -> 0 | Z13: ='24'!AX15 -> 0 | AA13: ='25'!AX15 -> 0 | AB13: ='26'!AX15 -> 0 | AC13: ='27'!AX15 -> 0 | AD13: ='28'!AX15 -> 0 | AE13: ='29'!AX15 -> 0 | AF13: ='30'!AX15 -> 0 | AG13: ='31'!AX15 -> 0 | AH13: =SUM(C13:AG13) -> 0 | AI13: =AH13*A13 -> 0
A14: 58 | B14: 尊美醇威士忌 | C14: ='1'!AX16 -> 0 | D14: ='2'!AX16 -> 0 | E14: ='3'!AX16 -> 0 | F14: ='4'!AX16 -> 0 | G14: ='5'!AX16 -> 0 | H14: ='6'!AX16 -> 0 | I14: ='7'!AX16 -> 0 | J14: ='8'!AX16 -> 0 | K14: ='9'!AX16 -> 0 | L14: ='10'!AX16 -> 0 | M14: ='11'!AX16 -> 0 | N14: ='12'!AX16 -> 0 | O14: ='13'!AX16 -> 0 | P14: ='14'!AX16 -> 0 | Q14: ='15'!AX16 -> 0 | R14: ='16'!AX16 -> 0 | S14: ='17'!AX16 -> 0 | T14: ='18'!AX16 -> 0 | U14: ='19'!AX16 -> 0 | V14: ='20'!AX16 -> 0 | W14: ='21'!AX16 -> 0 | X14: ='22'!AX16 -> 0 | Y14: ='23'!AX16 -> 0 | Z14: ='24'!AX16 -> 0 | AA14: ='25'!AX16 -> 0 | AB14: ='26'!AX16 -> 0 | AC14: ='27'!AX16 -> 0 | AD14: ='28'!AX16 -> 0 | AE14: ='29'!AX16 -> 0 | AF14: ='30'!AX16 -> 0 | AG14: ='31'!AX16 -> 0 | AH14: =SUM(C14:AG14) -> 0 | AI14: =AH14*A14 -> 0
A15: 68 | B15: 芝华士威士忌 | C15: ='1'!AX17 -> 0 | D15: ='2'!AX17 -> 0 | E15: ='3'!AX17 -> 0 | F15: ='4'!AX17 -> 0 | G15: ='5'!AX17 -> 0 | H15: ='6'!AX17 -> 0 | I15: ='7'!AX17 -> 0 | J15: ='8'!AX17 -> 0 | K15: ='9'!AX17 -> 0 | L15: ='10'!AX17 -> 0 | M15: ='11'!AX17 -> 0 | N15: ='12'!AX17 -> 0 | O15: ='13'!AX17 -> 0 | P15: ='14'!AX17 -> 0 | Q15: ='15'!AX17 -> 0 | R15: ='16'!AX17 -> 0 | S15: ='17'!AX17 -> 0 | T15: ='18'!AX17 -> 0 | U15: ='19'!AX17 -> 0 | V15: ='20'!AX17 -> 0 | W15: ='21'!AX17 -> 0 | X15: ='22'!AX17 -> 0 | Y15: ='23'!AX17 -> 0 | Z15: ='24'!AX17 -> 0 | AA15: ='25'!AX17 -> 0 | AB15: ='26'!AX17 -> 0 | AC15: ='27'!AX17 -> 0 | AD15: ='28'!AX17 -> 0 | AE15: ='29'!AX17 -> 0 | AF15: ='30'!AX17 -> 0 | AG15: ='31'!AX17 -> 0 | AH15: =SUM(C15:AG15) -> 0 | AI15: =AH15*A15 -> 0
A16: 108 | B16: 马爹利名仕干邑 | C16: ='1'!AX18 -> 0 | D16: ='2'!AX18 -> 0 | E16: ='3'!AX18 -> 0 | F16: ='4'!AX18 -> 0 | G16: ='5'!AX18 -> 0 | H16: ='6'!AX18 -> 0 | I16: ='7'!AX18 -> 0 | J16: ='8'!AX18 -> 0 | K16: ='9'!AX18 -> 0 | L16: ='10'!AX18 -> 0 | M16: ='11'!AX18 -> 0 | N16: ='12'!AX18 -> 0 | O16: ='13'!AX18 -> 0 | P16: ='14'!AX18 -> 0 | Q16: ='15'!AX18 -> 0 | R16: ='16'!AX18 -> 0 | S16: ='17'!AX18 -> 0 | T16: ='18'!AX18 -> 0 | U16: ='19'!AX18 -> 0 | V16: ='20'!AX18 -> 0 | W16: ='21'!AX18 -> 0 | X16: ='22'!AX18 -> 0 | Y16: ='23'!AX18 -> 0 | Z16: ='24'!AX18 -> 0 | AA16: ='25'!AX18 -> 0 | AB16: ='26'!AX18 -> 0 | AC16: ='27'!AX18 -> 0 | AD16: ='28'!AX18 -> 0 | AE16: ='29'!AX18 -> 0 | AF16: ='30'!AX18 -> 0 | AG16: ='31'!AX18 -> 0 | AH16: =SUM(C16:AG16) -> 0 | AI16: =AH16*A16 -> 0
A17: 68 | B17: 白熊啤酒 | C17: ='1'!AX19 -> 0 | D17: ='2'!AX19 -> 0 | E17: ='3'!AX19 -> 0 | F17: ='4'!AX19 -> 0 | G17: ='5'!AX19 -> 0 | H17: ='6'!AX19 -> 0 | I17: ='7'!AX19 -> 0 | J17: ='8'!AX19 -> 0 | K17: ='9'!AX19 -> 0 | L17: ='10'!AX19 -> 0 | M17: ='11'!AX19 -> 0 | N17: ='12'!AX19 -> 0 | O17: ='13'!AX19 -> 0 | P17: ='14'!AX19 -> 0 | Q17: ='15'!AX19 -> 0 | R17: ='16'!AX19 -> 0 | S17: ='17'!AX19 -> 0 | T17: ='18'!AX19 -> 0 | U17: ='19'!AX19 -> 0 | V17: ='20'!AX19 -> 0 | W17: ='21'!AX19 -> 0 | X17: ='22'!AX19 -> 0 | Y17: ='23'!AX19 -> 0 | Z17: ='24'!AX19 -> 0 | AA17: ='25'!AX19 -> 0 | AB17: ='26'!AX19 -> 0 | AC17: ='27'!AX19 -> 0 | AD17: ='28'!AX19 -> 0 | AE17: ='29'!AX19 -> 0 | AF17: ='30'!AX19 -> 0 | AG17: ='31'!AX19 -> 0 | AH17: =SUM(C17:AG17) -> 0 | AI17: =AH17*A17 -> 0
A18: 38 | B18: 青岛啤酒 | C18: ='1'!AX20 -> 0 | D18: ='2'!AX20 -> 0 | E18: ='3'!AX20 -> 0 | F18: ='4'!AX20 -> 0 | G18: ='5'!AX20 -> 0 | H18: ='6'!AX20 -> 0 | I18: ='7'!AX20 -> 0 | J18: ='8'!AX20 -> 0 | K18: ='9'!AX20 -> 0 | L18: ='10'!AX20 -> 0 | M18: ='11'!AX20 -> 0 | N18: ='12'!AX20 -> 0 | O18: ='13'!AX20 -> 0 | P18: ='14'!AX20 -> 0 | Q18: ='15'!AX20 -> 0 | R18: ='16'!AX20 -> 0 | S18: ='17'!AX20 -> 0 | T18: ='18'!AX20 -> 0 | U18: ='19'!AX20 -> 0 | V18: ='20'!AX20 -> 0 | W18: ='21'!AX20 -> 0 | X18: ='22'!AX20 -> 0 | Y18: ='23'!AX20 -> 0 | Z18: ='24'!AX20 -> 0 | AA18: ='25'!AX20 -> 0 | AB18: ='26'!AX20 -> 0 | AC18: ='27'!AX20 -> 0 | AD18: ='28'!AX20 -> 0 | AE18: ='29'!AX20 -> 0 | AF18: ='30'!AX20 -> 0 | AG18: ='31'!AX20 -> 0 | AH18: =SUM(C18:AG18) -> 0 | AI18: =AH18*A18 -> 0
A19: 98 | B19: 红酒 | C19: ='1'!AX21 -> 0 | D19: ='2'!AX21 -> 0 | E19: ='3'!AX21 -> 0 | F19: ='4'!AX21 -> 0 | G19: ='5'!AX21 -> 0 | H19: ='6'!AX21 -> 0 | I19: ='7'!AX21 -> 0 | J19: ='8'!AX21 -> 0 | K19: ='9'!AX21 -> 0 | L19: ='10'!AX21 -> 0 | M19: ='11'!AX21 -> 0 | N19: ='12'!AX21 -> 0 | O19: ='13'!AX21 -> 0 | P19: ='14'!AX21 -> 0 | Q19: ='15'!AX21 -> 0 | R19: ='16'!AX21 -> 0 | S19: ='17'!AX21 -> 0 | T19: ='18'!AX21 -> 0 | U19: ='19'!AX21 -> 0 | V19: ='20'!AX21 -> 0 | W19: ='21'!AX21 -> 0 | X19: ='22'!AX21 -> 0 | Y19: ='23'!AX21 -> 0 | Z19: ='24'!AX21 -> 0 | AA19: ='25'!AX21 -> 0 | AB19: ='26'!AX21 -> 0 | AC19: ='27'!AX21 -> 0 | AD19: ='28'!AX21 -> 0 | AE19: ='29'!AX21 -> 0 | AF19: ='30'!AX21 -> 0 | AG19: ='31'!AX21 -> 0 | AH19: =SUM(C19:AG19) -> 0 | AI19: =AH19*A19 -> 0
A20: 98 | B20: 白酒 | C20: ='1'!AX22 -> 0 | D20: ='2'!AX22 -> 0 | E20: ='3'!AX22 -> 0 | F20: ='4'!AX22 -> 0 | G20: ='5'!AX22 -> 0 | H20: ='6'!AX22 -> 0 | I20: ='7'!AX22 -> 0 | J20: ='8'!AX22 -> 0 | K20: ='9'!AX22 -> 0 | L20: ='10'!AX22 -> 0 | M20: ='11'!AX22 -> 0 | N20: ='12'!AX22 -> 0 | O20: ='13'!AX22 -> 0 | P20: ='14'!AX22 -> 0 | Q20: ='15'!AX22 -> 0 | R20: ='16'!AX22 -> 0 | S20: ='17'!AX22 -> 0 | T20: ='18'!AX22 -> 0 | U20: ='19'!AX22 -> 0 | V20: ='20'!AX22 -> 0 | W20: ='21'!AX22 -> 0 | X20: ='22'!AX22 -> 0 | Y20: ='23'!AX22 -> 0 | Z20: ='24'!AX22 -> 0 | AA20: ='25'!AX22 -> 0 | AB20: ='26'!AX22 -> 0 | AC20: ='27'!AX22 -> 0 | AD20: ='28'!AX22 -> 0 | AE20: ='29'!AX22 -> 0 | AF20: ='30'!AX22 -> 0 | AG20: ='31'!AX22 -> 0 | AH20: =SUM(C20:AG20) -> 0 | AI20: =AH20*A20 -> 0
A21: 38 | B21: 黄飞红麻辣花生 | C21: ='1'!AX23 -> 0 | D21: ='2'!AX23 -> 0 | E21: ='3'!AX23 -> 0 | F21: ='4'!AX23 -> 0 | G21: ='5'!AX23 -> 0 | H21: ='6'!AX23 -> 0 | I21: ='7'!AX23 -> 0 | J21: ='8'!AX23 -> 0 | K21: ='9'!AX23 -> 0 | L21: ='10'!AX23 -> 0 | M21: ='11'!AX23 -> 0 | N21: ='12'!AX23 -> 0 | O21: ='13'!AX23 -> 0 | P21: ='14'!AX23 -> 0 | Q21: ='15'!AX23 -> 0 | R21: ='16'!AX23 -> 0 | S21: ='17'!AX23 -> 0 | T21: ='18'!AX23 -> 0 | U21: ='19'!AX23 -> 0 | V21: ='20'!AX23 -> 0 | W21: ='21'!AX23 -> 0 | X21: ='22'!AX23 -> 0 | Y21: ='23'!AX23 -> 0 | Z21: ='24'!AX23 -> 0 | AA21: ='25'!AX23 -> 0 | AB21: ='26'!AX23 -> 0 | AC21: ='27'!AX23 -> 0 | AD21: ='28'!AX23 -> 0 | AE21: ='29'!AX23 -> 0 | AF21: ='30'!AX23 -> 0 | AG21: ='31'!AX23 -> 0 | AH21: =SUM(C21:AG21) -> 0 | AI21: =AH21*A21 -> 0
A22: 58 | B22: 薯片 | C22: ='1'!AX24 -> 0 | D22: ='2'!AX24 -> 0 | E22: ='3'!AX24 -> 0 | F22: ='4'!AX24 -> 0 | G22: ='5'!AX24 -> 0 | H22: ='6'!AX24 -> 0 | I22: ='7'!AX24 -> 0 | J22: ='8'!AX24 -> 0 | K22: ='9'!AX24 -> 0 | L22: ='10'!AX24 -> 0 | M22: ='11'!AX24 -> 0 | N22: ='12'!AX24 -> 0 | O22: ='13'!AX24 -> 0 | P22: ='14'!AX24 -> 0 | Q22: ='15'!AX24 -> 0 | R22: ='16'!AX24 -> 0 | S22: ='17'!AX24 -> 0 | T22: ='18'!AX24 -> 0 | U22: ='19'!AX24 -> 0 | V22: ='20'!AX24 -> 0 | W22: ='21'!AX24 -> 0 | X22: ='22'!AX24 -> 0 | Y22: ='23'!AX24 -> 0 | Z22: ='24'!AX24 -> 0 | AA22: ='25'!AX24 -> 0 | AB22: ='26'!AX24 -> 0 | AC22: ='27'!AX24 -> 0 | AD22: ='28'!AX24 -> 0 | AE22: ='29'!AX24 -> 0 | AF22: ='30'!AX24 -> 0 | AG22: ='31'!AX24 -> 0 | AH22: =SUM(C22:AG22) -> 0 | AI22: =AH22*A22 -> 0

Sheet 1
A1: 迷你吧入账单
A2: 序号 | B2: 品名 | C2: 房间号 单价 | Y2: 9500 | AX2: 总数 | AY2: 总金额
A4: 1 | B4: 圣培露 | C4: 60 | AX4: =SUM(D4:AW4) -> 0 | AY4: =AX4*C4 -> 0
A5: 2 | B5: 芙丝水 | C5: 60 | AX5: =SUM(D5:AW5) -> 0 | AY5: =AX5*C5 -> 0
A6: 3 | B6: 椰子水 | C6: 38 | AX6: =SUM(D6:AW6) -> 0 | AY6: =AX6*C6 -> 0
A7: 5 | B7: 梅子汁 | C7: 38 | AX7: =SUM(D7:AW7) -> 0 | AY7: =AX7*C7 -> 0
A8: 6 | B8: 百事可乐 | C8: 38 | AX8: =SUM(D8:AW8) -> 0 | AY8: =AX8*C8 -> 0
A9: 7 | B9: 健怡百事可乐 | C9: 38 | AX9: =SUM(D9:AW9) -> 0 | AY9: =AX9*C9 -> 0
A10: 8 | B10: 七喜 | C10: 38 | AX10: =SUM(D10:AW10) -> 0 | AY10: =AX10*C10 -> 0
A11: 9 | B11: 苏打水 | C11: 38 | AX11: =SUM(D11:AW11) -> 0 | AY11: =AX11*C11 -> 0
A12: 10 | B12: 汤力水 | C12: 38 | AX12: =SUM(D12:AW12) -> 0 | AY12: =AX12*C12 -> 0
AX13: =SUM(D13:AW13) -> 0 | AY13: =AX13*C13 -> 0
A14: 11 | B14: 必富达金酒 | C14: 58 | AX14: =SUM(D14:AW14) -> 0 | AY14: =AX14*C14 -> 0
A15: 12 | B15: 绝对伏特加 | C15: 58 | AX15: =SUM(D15:AW15) -> 0 | AY15: =AX15*C15 -> 0
A16: 13 | B16: 尊美醇威士忌 | C16: 58 | AX16: =SUM(D16:AW16) -> 0 | AY16: =AX16*C16 -> 0
A17: 14 | B17: 芝华士威士忌 | C17: 68 | AX17: =SUM(D17:AW17) -> 0 | AY17: =AX17*C17 -> 0
A18: 15 | B18: 马爹利名仕干邑 | C18: 108 | AX18: =SUM(D18:AW18) -> 0 | AY18: =AX18*C18 -> 0
A19: 16 | B19: 白熊啤酒 | C19: 68 | AX19: =SUM(D19:AW19) -> 0 | AY19: =AX19*C19 -> 0
A20: 17 | B20: 青岛啤酒 | C20: 38 | AX20: =SUM(D20:AW20) -> 0 | AY20: =AX20*C20 -> 0
A21: 18 | B21: 红葡萄酒 | C21: 98 | AX21: =SUM(D21:AW21) -> 0 | AY21: =AX21*C21 -> 0
A22: 19 | B22: 白葡萄酒 | C22: 98 | AX22: =SUM(D22:AW22) -> 0 | AY22: =AX22*C22 -> 0
A23: 20 | B23: 黄飞鸿 | C23: 38 | AX23: =SUM(D23:AW23) -> 0 | AY23: =AX23*C23 -> 0
A24: 21 | B24: 薯片 | C24: 58 | AX24: =SUM(D24:AW24) -> 0 | AY24: =AX24*C24 -> 0
C25: 总计个数 | D25: =SUM(D4:D24) -> 0 | E25: =SUM(E4:E24) -> 0 | F25: =SUM(F4:F24) -> 0 | G25: =SUM(G4:G24) -> 0 | H25: =SUM(H4:H24) -> 0 | I25: =SUM(I4:I24) -> 0 | J25: =SUM(J4:J24) -> 0 | K25: =SUM(K4:K24) -> 0 | ... AY25: =SUM(AY4:AY24) -> 0

Sheet 2
A1: 迷你吧入账单
A2: 序号 | B2: 品名 | C2: 房间号 单价 | Y2: 9500 | AX2: 总数 | AY2: 总金额
A4: 1 | B4: 圣培露 | C4: 60 | AX4: =SUM(D4:AW4) -> 0 | AY4: =AX4*C4 -> 0
A5: 2 | B5: 芙丝水 | C5: 60 | AX5: =SUM(D5:AW5) -> 0 | AY5: =AX5*C5 -> 0
A6: 3 | B6: 椰子水 | C6: 38 | AX6: =SUM(D6:AW6) -> 0 | AY6: =AX6*C6 -> 0
A7: 5 | B7: 梅子汁 | C7: 38 | AX7: =SUM(D7:AW7) -> 0 | AY7: =AX7*C7 -> 0
A8: 6 | B8: 百事可乐 | C8: 38 | AX8: =SUM(D8:AW8) -> 0 | AY8: =AX8*C8 -> 0
A9: 7 | B9: 健怡百事可乐 | C9: 38 | AX9: =SUM(D9:AW9) -> 0 | AY9: =AX9*C9 -> 0
A10: 8 | B10: 七喜 | C10: 38 | AX10: =SUM(D10:AW10) -> 0 | AY10: =AX10*C10 -> 0
A11: 9 | B11: 苏打水 | C11: 38 | AX11: =SUM(D11:AW11) -> 0 | AY11: =AX11*C11 -> 0
A12: 10 | B12: 汤力水 | C12: 38 | AX12: =SUM(D12:AW12) -> 0 | AY12: =AX12*C12 -> 0
AX13: =SUM(D13:AW13) -> 0 | AY13: =AX13*C13 -> 0
A14: 11 | B14: 必富达金酒 | C14: 58 | AX14: =SUM(D14:AW14) -> 0 | AY14: =AX14*C14 -> 0
A15: 12 | B15: 绝对伏特加 | C15: 58 | AX15: =SUM(D15:AW15) -> 0 | AY15: =AX15*C15 -> 0
A16: 13 | B16: 尊美醇威士忌 | C16: 58 | AX16: =SUM(D16:AW16) -> 0 | AY16: =AX16*C16 -> 0
A17: 14 | B17: 芝华士威士忌 | C17: 68 | AX17: =SUM(D17:AW17) -> 0 | AY17: =AX17*C17 -> 0
A18: 15 | B18: 马爹利名仕干邑 | C18: 108 | AX18: =SUM(D18:AW18) -> 0 | AY18: =AX18*C18 -> 0
A19: 16 | B19: 白熊啤酒 | C19: 68 | AX19: =SUM(D19:AW19) -> 0 | AY19: =AX19*C19 -> 0
A20: 17 | B20: 青岛啤酒 | C20: 38 | AX20: =SUM(D20:AW20) -> 0 | AY20: =AX20*C20 -> 0
A21: 18 | B21: 红葡萄酒 | C21: 98 | AX21: =SUM(D21:AW21) -> 0 | AY21: =AX21*C21 -> 0
A22: 19 | B22: 白葡萄酒 | C22: 98 | AX22: =SUM(D22:AW22) -> 0 | AY22: =AX22*C22 -> 0
A23: 20 | B23: 黄飞鸿 | C23: 38 | AX23: =SUM(D23:AW23) -> 0 | AY23: =AX23*C23 -> 0
A24: 21 | B24: 薯片 | C24: 58 | AX24: =SUM(D24:AW24) -> 0 | AY24: =AX24*C24 -> 0
C25: 总计个数 | D25: =SUM(D4:D24) -> 0 | E25: =SUM(E4:E24) -> 0 | F25: =SUM(F4:F24) -> 0 | G25: =SUM(G4:G24) -> 0 | H25: =SUM(H4:H24) -> 0 | I25: =SUM(I4:I24) -> 0 | J25: =SUM(J4:J24) -> 0 | K25: =SUM(K4:K24) -> 0 | ... AY25: =SUM(AY4:AY24) -> 0

Sheet 3
A1: 迷你吧入账单
A2: 序号 | B2: 品名 | C2: 房间号 单价 | Y2: 9500 | AX2: 总数 | AY2: 总金额
A4: 1 | B4: 圣培露 | C4: 60 | AX4: =SUM(D4:AW4) -> 0 | AY4: =AX4*C4 -> 0
A5: 2 | B5: 芙丝水 | C5: 60 | AX5: =SUM(D5:AW5) -> 0 | AY5: =AX5*C5 -> 0
A6: 3 | B6: 椰子水 | C6: 38 | AX6: =SUM(D6:AW6) -> 0 | AY6: =AX6*C6 -> 0
A7: 5 | B7: 梅子汁 | C7: 38 | AX7: =SUM(D7:AW7) -> 0 | AY7: =AX7*C7 -> 0
A8: 6 | B8: 百事可乐 | C8: 38 | AX8: =SUM(D8:AW8) -> 0 | AY8: =AX8*C8 -> 0
A9: 7 | B9: 健怡百事可乐 | C9: 38 | AX9: =SUM(D9:AW9) -> 0 | AY9: =AX9*C9 -> 0
A10: 8 | B10: 七喜 | C10: 38 | AX10: =SUM(D10:AW10) -> 0 | AY10: =AX10*C10 -> 0
A11: 9 | B11: 苏打水 | C11: 38 | AX11: =SUM(D11:AW11) -> 0 | AY11: =AX11*C11 -> 0
A12: 10 | B12: 汤力水 | C12: 38 | AX12: =SUM(D12:AW12) -> 0 | AY12: =AX12*C12 -> 0
AX13: =SUM(D13:AW13) -> 0 | AY13: =AX13*C13 -> 0
A14: 11 | B14: 必富达金酒 | C14: 58 | AX14: =SUM(D14:AW14) -> 0 | AY14: =AX14*C14 -> 0
A15: 12 | B15: 绝对伏特加 | C15: 58 | AX15: =SUM(D15:AW15) -> 0 | AY15: =AX15*C15 -> 0
A16: 13 | B16: 尊美醇威士忌 | C16: 58 | AX16: =SUM(D16:AW16) -> 0 | AY16: =AX16*C16 -> 0
A17: 14 | B17: 芝华士威士忌 | C17: 68 | AX17: =SUM(D17:AW17) -> 0 | AY17: =AX17*C17 -> 0
A18: 15 | B18: 马爹利名仕干邑 | C18: 108 | AX18: =SUM(D18:AW18) -> 0 | AY18: =AX18*C18 -> 0
A19: 16 | B19: 白熊啤酒 | C19: 68 | AX19: =SUM(D19:AW19) -> 0 | AY19: =AX19*C19 -> 0
A20: 17 | B20: 青岛啤酒 | C20: 38 | AX20: =SUM(D20:AW20) -> 0 | AY20: =AX20*C20 -> 0
A21: 18 | B21: 红葡萄酒 | C21: 98 | AX21: =SUM(D21:AW21) -> 0 | AY21: =AX21*C21 -> 0
A22: 19 | B22: 白葡萄酒 | C22: 98 | AX22: =SUM(D22:AW22) -> 0 | AY22: =AX22*C22 -> 0
A23: 20 | B23: 黄飞鸿 | C23: 38 | AX23: =SUM(D23:AW23) -> 0 | AY23: =AX23*C23 -> 0
A24: 21 | B24: 薯片 | C24: 58 | AX24: =SUM(D24:AW24) -> 0 | AY24: =AX24*C24 -> 0
C25: 总计个数 | D25: =SUM(D4:D24) -> 0 | E25: =SUM(E4:E24) -> 0 | F25: =SUM(F4:F24) -> 0 | G25: =SUM(G4:G24) -> 0 | H25: =SUM(H4:H24) -> 0 | I25: =SUM(I4:I24) -> 0 | J25: =SUM(J4:J24) -> 0 | K25: =SUM(K4:K24) -> 0 | ... AY25: =SUM(AY4:AY24) -> 0

Sheet 4
A1: 迷你吧入账单
A2: 序号 | B2: 品名 | C2: 房间号 单价 | Y2: 9500 | AX2: 总数 | AY2: 总金额
A4: 1 | B4: 圣培露 | C4: 60 | AX4: =SUM(D4:AW4) -> 0 | AY4: =AX4*C4 -> 0
A5: 2 | B5: 芙丝水 | C5: 60 | AX5: =SUM(D5:AW5) -> 0 | AY5: =AX5*C5 -> 0
A6: 3 | B6: 椰子水 | C6: 38 | AX6: =SUM(D6:AW6) -> 0 | AY6: =AX6*C6 -> 0
A7: 5 | B7: 梅子汁 | C7: 38 | AX7: =SUM(D7:AW7) -> 0 | AY7: =AX7*C7 -> 0
A8: 6 | B8: 百事可乐 | C8: 38 | AX8: =SUM(D8:AW8) -> 0 | AY8: =AX8*C8 -> 0
A9: 7 | B9: 健怡百事可乐 | C9: 38 | AX9: =SUM(D9:AW9) -> 0 | AY9: =AX9*C9 -> 0
A10: 8 | B10: 七喜 | C10: 38 | AX10: =SUM(D10:AW10) -> 0 | AY10: =AX10*C10 -> 0
A11: 9 | B11: 苏打水 | C11: 38 | AX11: =SUM(D11:AW11) -> 0 | AY11: =AX11*C11 -> 0
A12: 10 | B12: 汤力水 | C12: 38 | AX12: =SUM(D12:AW12) -> 0 | AY12: =AX12*C12 -> 0
AX13: =SUM(D13:AW13) -> 0 | AY13: =AX13*C13 -> 0
A14: 11 | B14: 必富达金酒 | C14: 58 | AX14: =SUM(D14:AW14) -> 0 | AY14: =AX14*C14 -> 0
A15: 12 | B15: 绝对伏特加 | C15: 58 | AX15: =SUM(D15:AW15) -> 0 | AY15: =AX15*C15 -> 0
A16: 13 | B16: 尊美醇威士忌 | C16: 58 | AX16: =SUM(D16:AW16) -> 0 | AY16: =AX16*C16 -> 0
A17: 14 | B17: 芝华士威士忌 | C17: 68 | AX17: =SUM(D17:AW17) -> 0 | AY17: =AX17*C17 -> 0
A18: 15 | B18: 马爹利名仕干邑 | C18: 108 | AX18: =SUM(D18:AW18) -> 0 | AY18: =AX18*C18 -> 0
A19: 16 | B19: 白熊啤酒 | C19: 68 | AX19: =SUM(D19:AW19) -> 0 | AY19: =AX19*C19 -> 0
A20: 17 | B20: 青岛啤酒 | C20: 38 | AX20: =SUM(D20:AW20) -> 0 | AY20: =AX20*C20 -> 0
A21: 18 | B21: 红葡萄酒 | C21: 98 | AX21: =SUM(D21:AW21) -> 0 | AY21: =AX21*C21 -> 0
A22: 19 | B22: 白葡萄酒 | C22: 98 | AX22: =SUM(D22:AW22) -> 0 | AY22: =AX22*C22 -> 0
A23: 20 | B23: 黄飞鸿 | C23: 38 | AX23: =SUM(D23:AW23) -> 0 | AY23: =AX23*C23 -> 0
A24: 21 | B24: 薯片 | C24: 58 | AX24: =SUM(D24:AW24) -> 0 | AY24: =AX24*C24 -> 0
C25: 总计个数 | D25: =SUM(D4:D24) -> 0 | E25: =SUM(E4:E24) -> 0 | F25: =SUM(F4:F24) -> 0 | G25: =SUM(G4:G24) -> 0 | H25: =SUM(H4:H24) -> 0 | I25: =SUM(I4:I24) -> 0 | J25: =SUM(J4:J24) -> 0 | K25: =SUM(K4:K24) -> 0 | ... AY25: =SUM(AY4:AY24) -> 0

Sheet 5
A1: 迷你吧入账单
A2: 序号 | B2: 品名 | C2: 房间号 单价 | Y2: 9500 | AX2: 总数 | AY2: 总金额
A4: 1 | B4: 圣培露 | C4: 60 | AX4: =SUM(D4:AW4) -> 0 | AY4: =AX4*C4 -> 0
A5: 2 | B5: 芙丝水 | C5: 60 | AX5: =SUM(D5:AW5) -> 0 | AY5: =AX5*C5 -> 0
A6: 3 | B6: 椰子水 | C6: 38 | AX6: =SUM(D6:AW6) -> 0 | AY6: =AX6*C6 -> 0
A7: 5 | B7: 梅子汁 | C7: 38 | AX7: =SUM(D7:AW7) -> 0 | AY7: =AX7*C7 -> 0
A8: 6 | B8: 百事可乐 | C8: 38 | AX8: =SUM(D8:AW8) -> 0 | AY8: =AX8*C8 -> 0
A9: 7 | B9: 健怡百事可乐 | C9: 38 | AX9: =SUM(D9:AW9) -> 0 | AY9: =AX9*C9 -> 0
A10: 8 | B10: 七喜 | C10: 38 | AX10: =SUM(D10:AW10) -> 0 | AY10: =AX10*C10 -> 0
A11: 9 | B11: 苏打水 | C11: 38 | AX11: =SUM(D11:AW11) -> 0 | AY11: =AX11*C11 -> 0
A12: 10 | B12: 汤力水 | C12: 38 | AX12: =SUM(D12:AW12) -> 0 | AY12: =AX12*C12 -> 0
AX13: =SUM(D13:AW13) -> 0 | AY13: =AX13*C13 -> 0
A14: 11 | B14: 必富达金酒 | C14: 58 | AX14: =SUM(D14:AW14) -> 0 | AY14: =AX14*C14 -> 0
A15: 12 | B15: 绝对伏特加 | C15: 58 | AX15: =SUM(D15:AW15) -> 0 | AY15: =AX15*C15 -> 0
A16: 13 | B16: 尊美醇威士忌 | C16: 58 | AX16: =SUM(D16:AW16) -> 0 | AY16: =AX16*C16 -> 0
A17: 14 | B17: 芝华士威士忌 | C17: 68 | AX17: =SUM(D17:AW17) -> 0 | AY17: =AX17*C17 -> 0
A18: 15 | B18: 马爹利名仕干邑 | C18: 108 | AX18: =SUM(D18:AW18) -> 0 | AY18: =AX18*C18 -> 0
A19: 16 | B19: 白熊啤酒 | C19: 68 | AX19: =SUM(D19:AW19) -> 0 | AY19: =AX19*C19 -> 0
A20: 17 | B20: 青岛啤酒 | C20: 38 | AX20: =SUM(D20:AW20) -> 0 | AY20: =AX20*C20 -> 0
A21: 18 | B21: 红葡萄酒 | C21: 98 | AX21: =SUM(D21:AW21) -> 0 | AY21: =AX21*C21 -> 0
A22: 19 | B22: 白葡萄酒 | C22: 98 | AX22: =SUM(D22:AW22) -> 0 | AY22: =AX22*C22 -> 0
A23: 20 | B23: 黄飞鸿 | C23: 38 | AX23: =SUM(D23:AW23) -> 0 | AY23: =AX23*C23 -> 0
A24: 21 | B24: 薯片 | C24: 58 | AX24: =SUM(D24:AW24) -> 0 | AY24: =AX24*C24 -> 0
C25: 总计个数 | D25: =SUM(D4:D24) -> 0 | E25: =SUM(E4:E24) -> 0 | F25: =SUM(F4:F24) -> 0 | G25: =SUM(G4:G24) -> 0 | H25: =SUM(H4:H24) -> 0 | I25: =SUM(I4:I24) -> 0 | J25: =SUM(J4:J24) -> 0 | K25: =SUM(K4:K24) -> 0 | ... AY25: =SUM(AY4:AY24) -> 0

Sheet 6
A1: 迷你吧入账单
A2: 序号 | B2: 品名 | C2: 房间号 单价 | Y2: 9500 | AX2: 总数 | AY2: 总金额
A4: 1 | B4: 圣培露 | C4: 60 | AX4: =SUM(D4:AW4) -> 0 | AY4: =AX4*C4 -> 0
A5: 2 | B5: 芙丝水 | C5: 60 | AX5: =SUM(D5:AW5) -> 0 | AY5: =AX5*C5 -> 0
A6: 3 | B6: 椰子水 | C6: 38 | AX6: =SUM(D6:AW6) -> 0 | AY6: =AX6*C6 -> 0
A7: 5 | B7: 梅子汁 | C7: 38 | AX7: =SUM(D7:AW7) -> 0 | AY7: =AX7*C7 -> 0
A8: 6 | B8: 百事可乐 | C8: 38 | AX8: =SUM(D8:AW8) -> 0 | AY8: =AX8*C8 -> 0
A9: 7 | B9: 健怡百事可乐 | C9: 38 | AX9: =SUM(D9:AW9) -> 0 | AY9: =AX9*C9 -> 0
A10: 8 | B10: 七喜 | C10: 38 | AX10: =SUM(D10:AW10) -> 0 | AY10: =AX10*C10 -> 0
A11: 9 | B11: 苏打水 | C11: 38 | AX11: =SUM(D11:AW11) -> 0 | AY11: =AX11*C11 -> 0
A12: 10 | B12: 汤力水 | C12: 38 | AX12: =SUM(D12:AW12) -> 0 | AY12: =AX12*C12 -> 0
AX13: =SUM(D13:AW13) -> 0 | AY13: =AX13*C13 -> 0
A14: 11 | B14: 必富达金酒 | C14: 58 | AX14: =SUM(D14:AW14) -> 0 | AY14: =AX14*C14 -> 0
A15: 12 | B15: 绝对伏特加 | C15: 58 | AX15: =SUM(D15:AW15) -> 0 | AY15: =AX15*C15 -> 0
A16: 13 | B16: 尊美醇威士忌 | C16: 58 | AX16: =SUM(D16:AW16) -> 0 | AY16: =AX16*C16 -> 0
A17: 14 | B17: 芝华士威士忌 | C17: 68 | AX17: =SUM(D17:AW17) -> 0 | AY17: =AX17*C17 -> 0
A18: 15 | B18: 马爹利名仕干邑 | C18: 108 | AX18: =SUM(D18:AW18) -> 0 | AY18: =AX18*C18 -> 0
A19: 16 | B19: 白熊啤酒 | C19: 68 | AX19: =SUM(D19:AW19) -> 0 | AY19: =AX19*C19 -> 0
A20: 17 | B20: 青岛啤酒 | C20: 38 | AX20: =SUM(D20:AW20) -> 0 | AY20: =AX20*C20 -> 0
A21: 18 | B21: 红葡萄酒 | C21: 98 | AX21: =SUM(D21:AW21) -> 0 | AY21: =AX21*C21 -> 0
A22: 19 | B22: 白葡萄酒 | C22: 98 | AX22: =SUM(D22:AW22) -> 0 | AY22: =AX22*C22 -> 0
A23: 20 | B23: 黄飞鸿 | C23: 38 | AX23: =SUM(D23:AW23) -> 0 | AY23: =AX23*C23 -> 0
A24: 21 | B24: 薯片 | C24: 58 | AX24: =SUM(D24:AW24) -> 0 | AY24: =AX24*C24 -> 0
C25: 总计个数 | D25: =SUM(D4:D24) -> 0 | E25: =SUM(E4:E24) -> 0 | F25: =SUM(F4:F24) -> 0 | G25: =SUM(G4:G24) -> 0 | H25: =SUM(H4:H24) -> 0 | I25: =SUM(I4:I24) -> 0 | J25: =SUM(J4:J24) -> 0 | K25: =SUM(K4:K24) -> 0 | ... AY25: =SUM(AY4:AY24) -> 0

Sheet 7
A1: 迷你吧入账单
A2: 序号 | B2: 品名 | C2: 房间号 单价 | Y2: 9500 | AX2: 总数 | AY2: 总金额
A4: 1 | B4: 圣培露 | C4: 60 | AX4: =SUM(D4:AW4) -> 0 | AY4: =AX4*C4 -> 0
A5: 2 | B5: 芙丝水 | C5: 60 | AX5: =SUM(D5:AW5) -> 0 | AY5: =AX5*C5 -> 0
A6: 3 | B6: 椰子水 | C6: 38 | AX6: =SUM(D6:AW6) -> 0 | AY6: =AX6*C6 -> 0
A7: 5 | B7: 梅子汁 | C7: 38 | AX7: =SUM(D7:AW7) -> 0 | AY7: =AX7*C7 -> 0
A8: 6 | B8: 百事可乐 | C8: 38 | AX8: =SUM(D8:AW8) -> 0 | AY8: =AX8*C8 -> 0
A9: 7 | B9: 健怡百事可乐 | C9: 38 | AX9: =SUM(D9:AW9) -> 0 | AY9: =AX9*C9 -> 0
A10: 8 | B10: 七喜 | C10: 38 | AX10: =SUM(D10:AW10) -> 0 | AY10: =AX10*C10 -> 0
A11: 9 | B11: 苏打水 | C11: 38 | AX11: =SUM(D11:AW11) -> 0 | AY11: =AX11*C11 -> 0
A12: 10 | B12: 汤力水 | C12: 38 | AX12: =SUM(D12:AW12) -> 0 | AY12: =AX12*C12 -> 0
AX13: =SUM(D13:AW13) -> 0 | AY13: =AX13*C13 -> 0
A14: 11 | B14: 必富达金酒 | C14: 58 | AX14: =SUM(D14:AW14) -> 0 | AY14: =AX14*C14 -> 0
A15: 12 | B15: 绝对伏特加 | C15: 58 | AX15: =SUM(D15:AW15) -> 0 | AY15: =AX15*C15 -> 0
A16: 13 | B16: 尊美醇威士忌 | C16: 58 | AX16: =SUM(D16:AW16) -> 0 | AY16: =AX16*C16 -> 0
A17: 14 | B17: 芝华士威士忌 | C17: 68 | AX17: =SUM(D17:AW17) -> 0 | AY17: =AX17*C17 -> 0
A18: 15 | B18: 马爹利名仕干邑 | C18: 108 | AX18: =SUM(D18:AW18) -> 0 | AY18: =AX18*C18 -> 0
A19: 16 | B19: 白熊啤酒 | C19: 68 | AX19: =SUM(D19:AW19) -> 0 | AY19: =AX19*C19 -> 0
A20: 17 | B20: 青岛啤酒 | C20: 38 | AX20: =SUM(D20:AW20) -> 0 | AY20: =AX20*C20 -> 0
A21: 18 | B21: 红葡萄酒 | C21: 98 | AX21: =SUM(D21:AW21) -> 0 | AY21: =AX21*C21 -> 0
A22: 19 | B22: 白葡萄酒 | C22: 98 | AX22: =SUM(D22:AW22) -> 0 | AY22: =AX22*C22 -> 0
A23: 20 | B23: 黄飞鸿 | C23: 38 | AX23: =SUM(D23:AW23) -> 0 | AY23: =AX23*C23 -> 0
A24: 21 | B24: 薯片 | C24: 58 | AX24: =SUM(D24:AW24) -> 0 | AY24: =AX24*C24 -> 0
C25: 总计个数 | D25: =SUM(D4:D24) -> 0 | E25: =SUM(E4:E24) -> 0 | F25: =SUM(F4:F24) -> 0 | G25: =SUM(G4:G24) -> 0 | H25: =SUM(H4:H24) -> 0 | I25: =SUM(I4:I24) -> 0 | J25: =SUM(J4:J24) -> 0 | K25: =SUM(K4:K24) -> 0 | ... AY25: =SUM(AY4:AY24) -> 0

Sheet 8
A1: 迷你吧入账单
A2: 序号 | B2: 品名 | C2: 房间号 单价 | Y2: 9500 | AX2: 总数 | AY2: 总金额
A4: 1 | B4: 圣培露 | C4: 60 | AX4: =SUM(D4:AW4) -> 0 | AY4: =AX4*C4 -> 0
A5: 2 | B5: 芙丝水 | C5: 60 | AX5: =SUM(D5:AW5) -> 0 | AY5: =AX5*C5 -> 0
A6: 3 | B6: 椰子水 | C6: 38 | AX6: =SUM(D6:AW6) -> 0 | AY6: =AX6*C6 -> 0
A7: 5 | B7: 梅子汁 | C7: 38 | AX7: =SUM(D7:AW7) -> 0 | AY7: =AX7*C7 -> 0
A8: 6 | B8: 百事可乐 | C8: 38 | AX8: =SUM(D8:AW8) -> 0 | AY8: =AX8*C8 -> 0
A9: 7 | B9: 健怡百事可乐 | C9: 38 | AX9: =SUM(D9:AW9) -> 0 | AY9: =AX9*C9 -> 0
A10: 8 | B10: 七喜 | C10: 38 | AX10: =SUM(D10:AW10) -> 0 | AY10: =AX10*C10 -> 0
A11: 9 | B11: 苏打水 | C11: 38 | AX11: =SUM(D11:AW11) -> 0 | AY11: =AX11*C11 -> 0
A12: 10 | B12: 汤力水 | C12: 38 | AX12: =SUM(D12:AW12) -> 0 | AY12: =AX12*C12 -> 0
AX13: =SUM(D13:AW13) -> 0 | AY13: =AX13*C13 -> 0
A14: 11 | B14: 必富达金酒 | C14: 58 | AX14: =SUM(D14:AW14) -> 0 | AY14: =AX14*C14 -> 0
A15: 12 | B15: 绝对伏特加 | C15: 58 | AX15: =SUM(D15:AW15) -> 0 | AY15: =AX15*C15 -> 0
A16: 13 | B16: 尊美醇威士忌 | C16: 58 | AX16: =SUM(D16:AW16) -> 0 | AY16: =AX16*C16 -> 0
A17: 14 | B17: 芝华士威士忌 | C17: 68 | AX17: =SUM(D17:AW17) -> 0 | AY17: =AX17*C17 -> 0
A18: 15 | B18: 马爹利名仕干邑 | C18: 108 | AX18: =SUM(D18:AW18) -> 0 | AY18: =AX18*C18 -> 0
A19: 16 | B19: 白熊啤酒 | C19: 68 | AX19: =SUM(D19:AW19) -> 0 | AY19: =AX19*C19 -> 0
A20: 17 | B20: 青岛啤酒 | C20: 38 | AX20: =SUM(D20:AW20) -> 0 | AY20: =AX20*C20 -> 0
A21: 18 | B21: 红葡萄酒 | C21: 98 | AX21: =SUM(D21:AW21) -> 0 | AY21: =AX21*C21 -> 0
A22: 19 | B22: 白葡萄酒 | C22: 98 | AX22: =SUM(D22:AW22) -> 0 | AY22: =AX22*C22 -> 0
A23: 20 | B23: 黄飞鸿 | C23: 38 | AX23: =SUM(D23:AW23) -> 0 | AY23: =AX23*C23 -> 0
A24: 21 | B24: 薯片 | C24: 58 | AX24: =SUM(D24:AW24) -> 0 | AY24: =AX24*C24 -> 0
C25: 总计个数 | D25: =SUM(D4:D24) -> 0 | E25: =SUM(E4:E24) -> 0 | F25: =SUM(F4:F24) -> 0 | G25: =SUM(G4:G24) -> 0 | H25: =SUM(H4:H24) -> 0 | I25: =SUM(I4:I24) -> 0 | J25: =SUM(J4:J24) -> 0 | K25: =SUM(K4:K24) -> 0 | ... AY25: =SUM(AY4:AY24) -> 0

Sheet 9
A1: 迷你吧入账单
A2: 序号 | B2: 品名 | C2: 房间号 单价 | Y2: 9500 | AX2: 总数 | AY2: 总金额
A4: 1 | B4: 圣培露 | C4: 60 | AX4: =SUM(D4:AW4) -> 0 | AY4: =AX4*C4 -> 0
A5: 2 | B5: 芙丝水 | C5: 60 | AX5: =SUM(D5:AW5) -> 0 | AY5: =AX5*C5 -> 0
A6: 3 | B6: 椰子水 | C6: 38 | AX6: =SUM(D6:AW6) -> 0 | AY6: =AX6*C6 -> 0
A7: 5 | B7: 梅子汁 | C7: 38 | AX7: =SUM(D7:AW7) -> 0 | AY7: =AX7*C7 -> 0
A8: 6 | B8: 百事可乐 | C8: 38 | AX8: =SUM(D8:AW8) -> 0 | AY8: =AX8*C8 -> 0
A9: 7 | B9: 健怡百事可乐 | C9: 38 | AX9: =SUM(D9:AW9) -> 0 | AY9: =AX9*C9 -> 0
A10: 8 | B10: 七喜 | C10: 38 | AX10: =SUM(D10:AW10) -> 0 | AY10: =AX10*C10 -> 0
A11: 9 | B11: 苏打水 | C11: 38 | AX11: =SUM(D11:AW11) -> 0 | AY11: =AX11*C11 -> 0
A12: 10 | B12: 汤力水 | C12: 38 | AX12: =SUM(D12:AW12) -> 0 | AY12: =AX12*C12 -> 0
AX13: =SUM(D13:AW13) -> 0 | AY13: =AX13*C13 -> 0
A14: 11 | B14: 必富达金酒 | C14: 58 | AX14: =SUM(D14:AW14) -> 0 | AY14: =AX14*C14 -> 0
A15: 12 | B15: 绝对伏特加 | C15: 58 | AX15: =SUM(D15:AW15) -> 0 | AY15: =AX15*C15 -> 0
A16: 13 | B16: 尊美醇威士忌 | C16: 58 | AX16: =SUM(D16:AW16) -> 0 | AY16: =AX16*C16 -> 0
A17: 14 | B17: 芝华士威士忌 | C17: 68 | AX17: =SUM(D17:AW17) -> 0 | AY17: =AX17*C17 -> 0
A18: 15 | B18: 马爹利名仕干邑 | C18: 108 | AX18: =SUM(D18:AW18) -> 0 | AY18: =AX18*C18 -> 0
A19: 16 | B19: 白熊啤酒 | C19: 68 | AX19: =SUM(D19:AW19) -> 0 | AY19: =AX19*C19 -> 0
A20: 17 | B20: 青岛啤酒 | C20: 38 | AX20: =SUM(D20:AW20) -> 0 | AY20: =AX20*C20 -> 0
A21: 18 | B21: 红葡萄酒 | C21: 98 | AX21: =SUM(D21:AW21) -> 0 | AY21: =AX21*C21 -> 0
A22: 19 | B22: 白葡萄酒 | C22: 98 | AX22: =SUM(D22:AW22) -> 0 | AY22: =AX22*C22 -> 0
A23: 20 | B23: 黄飞鸿 | C23: 38 | AX23: =SUM(D23:AW23) -> 0 | AY23: =AX23*C23 -> 0
A24: 21 | B24: 薯片 | C24: 58 | AX24: =SUM(D24:AW24) -> 0 | AY24: =AX24*C24 -> 0
C25: 总计个数 | D25: =SUM(D4:D24) -> 0 | E25: =SUM(E4:E24) -> 0 | F25: =SUM(F4:F24) -> 0 | G25: =SUM(G4:G24) -> 0 | H25: =SUM(H4:H24) -> 0 | I25: =SUM(I4:I24) -> 0 | J25: =SUM(J4:J24) -> 0 | K25: =SUM(K4:K24) -> 0 | ... AY25: =SUM(AY4:AY24) -> 0

Sheet 10
A1: 迷你吧入账单
A2: 序号 | B2: 品名 | C2: 房间号 单价 | Y2: 9500 | AX2: 总数 | AY2: 总金额
A4: 1 | B4: 圣培露 | C4: 60 | AX4: =SUM(D4:AW4) -> 0 | AY4: =AX4*C4 -> 0
A5: 2 | B5: 芙丝水 | C5: 60 | AX5: =SUM(D5:AW5) -> 0 | AY5: =AX5*C5 -> 0
A6: 3 | B6: 椰子水 | C6: 38 | AX6: =SUM(D6:AW6) -> 0 | AY6: =AX6*C6 -> 0
A7: 5 | B7: 梅子汁 | C7: 38 | AX7: =SUM(D7:AW7) -> 0 | AY7: =AX7*C7 -> 0
A8: 6 | B8: 百事可乐 | C8: 38 | AX8: =SUM(D8:AW8) -> 0 | AY8: =AX8*C8 -> 0
A9: 7 | B9: 健怡百事可乐 | C9: 38 | AX9: =SUM(D9:AW9) -> 0 | AY9: =AX9*C9 -> 0
A10: 8 | B10: 七喜 | C10: 38 | AX10: =SUM(D10:AW10) -> 0 | AY10: =AX10*C10 -> 0
A11: 9 | B11: 苏打水 | C11: 38 | AX11: =SUM(D11:AW11) -> 0 | AY11: =AX11*C11 -> 0
A12: 10 | B12: 汤力水 | C12: 38 | AX12: =SUM(D12:AW12) -> 0 | AY12: =AX12*C12 -> 0
AX13: =SUM(D13:AW13) -> 0 | AY13: =AX13*C13 -> 0
A14: 11 | B14: 必富达金酒 | C14: 58 | AX14: =SUM(D14:AW14) -> 0 | AY14: =AX14*C14 -> 0
A15: 12 | B15: 绝对伏特加 | C15: 58 | AX15: =SUM(D15:AW15) -> 0 | AY15: =AX15*C15 -> 0
A16: 13 | B16: 尊美醇威士忌 | C16: 58 | AX16: =SUM(D16:AW16) -> 0 | AY16: =AX16*C16 -> 0
A17: 14 | B17: 芝华士威士忌 | C17: 68 | AX17: =SUM(D17:AW17) -> 0 | AY17: =AX17*C17 -> 0
A18: 15 | B18: 马爹利名仕干邑 | C18: 108 | AX18: =SUM(D18:AW18) -> 0 | AY18: =AX18*C18 -> 0
A19: 16 | B19: 白熊啤酒 | C19: 68 | AX19: =SUM(D19:AW19) -> 0 | AY19: =AX19*C19 -> 0
A20: 17 | B20: 青岛啤酒 | C20: 38 | AX20: =SUM(D20:AW20) -> 0 | AY20: =AX20*C20 -> 0
A21: 18 | B21: 红葡萄酒 | C21: 98 | AX21: =SUM(D21:AW21) -> 0 | AY21: =AX21*C21 -> 0
A22: 19 | B22: 白葡萄酒 | C22: 98 | AX22: =SUM(D22:AW22) -> 0 | AY22: =AX22*C22 -> 0
A23: 20 | B23: 黄飞鸿 | C23: 38 | AX23: =SUM(D23:AW23) -> 0 | AY23: =AX23*C23 -> 0
A24: 21 | B24: 薯片 | C24: 58 | AX24: =SUM(D24:AW24) -> 0 | AY24: =AX24*C24 -> 0
C25: 总计个数 | D25: =SUM(D4:D24) -> 0 | E25: =SUM(E4:E24) -> 0 | F25: =SUM(F4:F24) -> 0 | G25: =SUM(G4:G24) -> 0 | H25: =SUM(H4:H24) -> 0 | I25: =SUM(I4:I24) -> 0 | J25: =SUM(J4:J24) -> 0 | K25: =SUM(K4:K24) -> 0 | ... AY25: =SUM(AY4:AY24) -> 0

Sheet 11
A1: 迷你吧入账单
A2: 序号 | B2: 品名 | C2: 房间号 单价 | Y2: 9500 | AX2: 总数 | AY2: 总金额
A4: 1 | B4: 圣培露 | C4: 60 | AX4: =SUM(D4:AW4) -> 0 | AY4: =AX4*C4 -> 0
A5: 2 | B5: 芙丝水 | C5: 60 | AX5: =SUM(D5:AW5) -> 0 | AY5: =AX5*C5 -> 0
A6: 3 | B6: 椰子水 | C6: 38 | AX6: =SUM(D6:AW6) -> 0 | AY6: =AX6*C6 -> 0
A7: 5 | B7: 梅子汁 | C7: 38 | AX7: =SUM(D7:AW7) -> 0 | AY7: =AX7*C7 -> 0
A8: 6 | B8: 百事可乐 | C8: 38 | AX8: =SUM(D8:AW8) -> 0 | AY8: =AX8*C8 -> 0
A9: 7 | B9: 健怡百事可乐 | C9: 38 | AX9: =SUM(D9:AW9) -> 0 | AY9: =AX9*C9 -> 0
A10: 8 | B10: 七喜 | C10: 38 | AX10: =SUM(D10:AW10) -> 0 | AY10: =AX10*C10 -> 0
A11: 9 | B11: 苏打水 | C11: 38 | AX11: =SUM(D11:AW11) -> 0 | AY11: =AX11*C11 -> 0
A12: 10 | B12: 汤力水 | C12: 38 | AX12: =SUM(D12:AW12) -> 0 | AY12: =AX12*C12 -> 0
AX13: =SUM(D13:AW13) -> 0 | AY13: =AX13*C13 -> 0
A14: 11 | B14: 必富达金酒 | C14: 58 | AX14: =SUM(D14:AW14) -> 0 | AY14: =AX14*C14 -> 0
A15: 12 | B15: 绝对伏特加 | C15: 58 | AX15: =SUM(D15:AW15) -> 0 | AY15: =AX15*C15 -> 0
A16: 13 | B16: 尊美醇威士忌 | C16: 58 | AX16: =SUM(D16:AW16) -> 0 | AY16: =AX16*C16 -> 0
A17: 14 | B17: 芝华士威士忌 | C17: 68 | AX17: =SUM(D17:AW17) -> 0 | AY17: =AX17*C17 -> 0
A18: 15 | B18: 马爹利名仕干邑 | C18: 108 | AX18: =SUM(D18:AW18) -> 0 | AY18: =AX18*C18 -> 0
A19: 16 | B19: 白熊啤酒 | C19: 68 | AX19: =SUM(D19:AW19) -> 0 | AY19: =AX19*C19 -> 0
A20: 17 | B20: 青岛啤酒 | C20: 38 | AX20: =SUM(D20:AW20) -> 0 | AY20: =AX20*C20 -> 0
A21: 18 | B21: 红葡萄酒 | C21: 98 | AX21: =SUM(D21:AW21) -> 0 | AY21: =AX21*C21 -> 0
A22: 19 | B22: 白葡萄酒 | C22: 98 | AX22: =SUM(D22:AW22) -> 0 | AY22: =AX22*C22 -> 0
A23: 20 | B23: 黄飞鸿 | C23: 38 | AX23: =SUM(D23:AW23) -> 0 | AY23: =AX23*C23 -> 0
A24: 21 | B24: 薯片 | C24: 58 | AX24: =SUM(D24:AW24) -> 0 | AY24: =AX24*C24 -> 0
C25: 总计个数 | D25: =SUM(D4:D24) -> 0 | E25: =SUM(E4:E24) -> 0 | F25: =SUM(F4:F24) -> 0 | G25: =SUM(G4:G24) -> 0 | H25: =SUM(H4:H24) -> 0 | I25: =SUM(I4:I24) -> 0 | J25: =SUM(J4:J24) -> 0 | K25: =SUM(K4:K24) -> 0 | ... AY25: =SUM(AY4:AY24) -> 0

Sheet 12
A1: 迷你吧入账单
A2: 序号 | B2: 品名 | C2: 房间号 单价 | Y2: 9500 | AX2: 总数 | AY2: 总金额
A4: 1 | B4: 圣培露 | C4: 60 | AX4: =SUM(D4:AW4) -> 0 | AY4: =AX4*C4 -> 0
A5: 2 | B5: 芙丝水 | C5: 60 | AX5: =SUM(D5:AW5) -> 0 | AY5: =AX5*C5 -> 0
A6: 3 | B6: 椰子水 | C6: 38 | AX6: =SUM(D6:AW6) -> 0 | AY6: =AX6*C6 -> 0
A7: 5 | B7: 梅子汁 | C7: 38 | AX7: =SUM(D7:AW7) -> 0 | AY7: =AX7*C7 -> 0
A8: 6 | B8: 百事可乐 | C8: 38 | AX8: =SUM(D8:AW8) -> 0 | AY8: =AX8*C8 -> 0
A9: 7 | B9: 健怡百事可乐 | C9: 38 | AX9: =SUM(D9:AW9) -> 0 | AY9: =AX9*C9 -> 0
A10: 8 | B10: 七喜 | C10: 38 | AX10: =SUM(D10:AW10) -> 0 | AY10: =AX10*C10 -> 0
A11: 9 | B11: 苏打水 | C11: 38 | AX11: =SUM(D11:AW11) -> 0 | AY11: =AX11*C11 -> 0
A12: 10 | B12: 汤力水 | C12: 38 | AX12: =SUM(D12:AW12) -> 0 | AY12: =AX12*C12 -> 0
AX13: =SUM(D13:AW13) -> 0 | AY13: =AX13*C13 -> 0
A14: 11 | B14: 必富达金酒 | C14: 58 | AX14: =SUM(D14:AW14) -> 0 | AY14: =AX14*C14 -> 0
A15: 12 | B15: 绝对伏特加 | C15: 58 | AX15: =SUM(D15:AW15) -> 0 | AY15: =AX15*C15 -> 0
A16: 13 | B16: 尊美醇威士忌 | C16: 58 | AX16: =SUM(D16:AW16) -> 0 | AY16: =AX16*C16 -> 0
A17: 14 | B17: 芝华士威士忌 | C17: 68 | AX17: =SUM(D17:AW17) -> 0 | AY17: =AX17*C17 -> 0
A18: 15 | B18: 马爹利名仕干邑 | C18: 108 | AX18: =SUM(D18:AW18) -> 0 | AY18: =AX18*C18 -> 0
A19: 16 | B19: 白熊啤酒 | C19: 68 | AX19: =SUM(D19:AW19) -> 0 | AY19: =AX19*C19 -> 0
A20: 17 | B20: 青岛啤酒 | C20: 38 | AX20: =SUM(D20:AW20) -> 0 | AY20: =AX20*C20 -> 0
A21: 18 | B21: 红葡萄酒 | C21: 98 | AX21: =SUM(D21:AW21) -> 0 | AY21: =AX21*C21 -> 0
A22: 19 | B22: 白葡萄酒 | C22: 98 | AX22: =SUM(D22:AW22) -> 0 | AY22: =AX22*C22 -> 0
A23: 20 | B23: 黄飞鸿 | C23: 38 | AX23: =SUM(D23:AW23) -> 0 | AY23: =AX23*C23 -> 0
A24: 21 | B24: 薯片 | C24: 58 | AX24: =SUM(D24:AW24) -> 0 | AY24: =AX24*C24 -> 0
C25: 总计个数 | D25: =SUM(D4:D24) -> 0 | E25: =SUM(E4:E24) -> 0 | F25: =SUM(F4:F24) -> 0 | G25: =SUM(G4:G24) -> 0 | H25: =SUM(H4:H24) -> 0 | I25: =SUM(I4:I24) -> 0 | J25: =SUM(J4:J24) -> 0 | K25: =SUM(K4:K24) -> 0 | ... AY25: =SUM(AY4:AY24) -> 0

Sheet 13
A1: 迷你吧入账单
A2: 序号 | B2: 品名 | C2: 房间号 单价 | Y2: 9500 | AX2: 总数 | AY2: 总金额
A4: 1 | B4: 圣培露 | C4: 60 | AX4: =SUM(D4:AW4) -> 0 | AY4: =AX4*C4 -> 0
A5: 2 | B5: 芙丝水 | C5: 60 | AX5: =SUM(D5:AW5) -> 0 | AY5: =AX5*C5 -> 0
A6: 3 | B6: 椰子水 | C6: 38 | AX6: =SUM(D6:AW6) -> 0 | AY6: =AX6*C6 -> 0
A7: 5 | B7: 梅子汁 | C7: 38 | AX7: =SUM(D7:AW7) -> 0 | AY7: =AX7*C7 -> 0
A8: 6 | B8: 百事可乐 | C8: 38 | AX8: =SUM(D8:AW8) -> 0 | AY8: =AX8*C8 -> 0
A9: 7 | B9: 健怡百事可乐 | C9: 38 | AX9: =SUM(D9:AW9) -> 0 | AY9: =AX9*C9 -> 0
A10: 8 | B10: 七喜 | C10: 38 | AX10: =SUM(D10:AW10) -> 0 | AY10: =AX10*C10 -> 0
A11: 9 | B11: 苏打水 | C11: 38 | AX11: =SUM(D11:AW11) -> 0 | AY11: =AX11*C11 -> 0
A12: 10 | B12: 汤力水 | C12: 38 | AX12: =SUM(D12:AW12) -> 0 | AY12: =AX12*C12 -> 0
AX13: =SUM(D13:AW13) -> 0 | AY13: =AX13*C13 -> 0
A14: 11 | B14: 必富达金酒 | C14: 58 | AX14: =SUM(D14:AW14) -> 0 | AY14: =AX14*C14 -> 0
A15: 12 | B15: 绝对伏特加 | C15: 58 | AX15: =SUM(D15:AW15) -> 0 | AY15: =AX15*C15 -> 0
A16: 13 | B16: 尊美醇威士忌 | C16: 58 | AX16: =SUM(D16:AW16) -> 0 | AY16: =AX16*C16 -> 0
A17: 14 | B17: 芝华士威士忌 | C17: 68 | AX17: =SUM(D17:AW17) -> 0 | AY17: =AX17*C17 -> 0
A18: 15 | B18: 马爹利名仕干邑 | C18: 108 | AX18: =SUM(D18:AW18) -> 0 | AY18: =AX18*C18 -> 0
A19: 16 | B19: 白熊啤酒 | C19: 68 | AX19: =SUM(D19:AW19) -> 0 | AY19: =AX19*C19 -> 0
A20: 17 | B20: 青岛啤酒 | C20: 38 | AX20: =SUM(D20:AW20) -> 0 | AY20: =AX20*C20 -> 0
A21: 18 | B21: 红葡萄酒 | C21: 98 | AX21: =SUM(D21:AW21) -> 0 | AY21: =AX21*C21 -> 0
A22: 19 | B22: 白葡萄酒 | C22: 98 | AX22: =SUM(D22:AW22) -> 0 | AY22: =AX22*C22 -> 0
A23: 20 | B23: 黄飞鸿 | C23: 38 | AX23: =SUM(D23:AW23) -> 0 | AY23: =AX23*C23 -> 0
A24: 21 | B24: 薯片 | C24: 58 | AX24: =SUM(D24:AW24) -> 0 | AY24: =AX24*C24 -> 0
C25: 总计个数 | D25: =SUM(D4:D24) -> 0 | E25: =SUM(E4:E24) -> 0 | F25: =SUM(F4:F24) -> 0 | G25: =SUM(G4:G24) -> 0 | H25: =SUM(H4:H24) -> 0 | I25: =SUM(I4:I24) -> 0 | J25: =SUM(J4:J24) -> 0 | K25: =SUM(K4:K24) -> 0 | ... AY25: =SUM(AY4:AY24) -> 0

Sheet 14
A1: 迷你吧入账单
A2: 序号 | B2: 品名 | C2: 房间号 单价 | Y2: 9500 | AX2: 总数 | AY2: 总金额
A4: 1 | B4: 圣培露 | C4: 60 | AX4: =SUM(D4:AW4) -> 0 | AY4: =AX4*C4 -> 0
A5: 2 | B5: 芙丝水 | C5: 60 | AX5: =SUM(D5:AW5) -> 0 | AY5: =AX5*C5 -> 0
A6: 3 | B6: 椰子水 | C6: 38 | AX6: =SUM(D6:AW6) -> 0 | AY6: =AX6*C6 -> 0
A7: 5 | B7: 梅子汁 | C7: 38 | AX7: =SUM(D7:AW7) -> 0 | AY7: =AX7*C7 -> 0
A8: 6 | B8: 百事可乐 | C8: 38 | AX8: =SUM(D8:AW8) -> 0 | AY8: =AX8*C8 -> 0
A9: 7 | B9: 健怡百事可乐 | C9: 38 | AX9: =SUM(D9:AW9) -> 0 | AY9: =AX9*C9 -> 0
A10: 8 | B10: 七喜 | C10: 38 | AX10: =SUM(D10:AW10) -> 0 | AY10: =AX10*C10 -> 0
A11: 9 | B11: 苏打水 | C11: 38 | AX11: =SUM(D11:AW11) -> 0 | AY11: =AX11*C11 -> 0
A12: 10 | B12: 汤力水 | C12: 38 | AX12: =SUM(D12:AW12) -> 0 | AY12: =AX12*C12 -> 0
AX13: =SUM(D13:AW13) -> 0 | AY13: =AX13*C13 -> 0
A14: 11 | B14: 必富达金酒 | C14: 58 | AX14: =SUM(D14:AW14) -> 0 | AY14: =AX14*C14 -> 0
A15: 12 | B15: 绝对伏特加 | C15: 58 | AX15: =SUM(D15:AW15) -> 0 | AY15: =AX15*C15 -> 0
A16: 13 | B16: 尊美醇威士忌 | C16: 58 | AX16: =SUM(D16:AW16) -> 0 | AY16: =AX16*C16 -> 0
A17: 14 | B17: 芝华士威士忌 | C17: 68 | AX17: =SUM(D17:AW17) -> 0 | AY17: =AX17*C17 -> 0
A18: 15 | B18: 马爹利名仕干邑 | C18: 108 | AX18: =SUM(D18:AW18) -> 0 | AY18: =AX18*C18 -> 0
A19: 16 | B19: 白熊啤酒 | C19: 68 | AX19: =SUM(D19:AW19) -> 0 | AY19: =AX19*C19 -> 0
A20: 17 | B20: 青岛啤酒 | C20: 38 | AX20: =SUM(D20:AW20) -> 0 | AY20: =AX20*C20 -> 0
A21: 18 | B21: 红葡萄酒 | C21: 98 | AX21: =SUM(D21:AW21) -> 0 | AY21: =AX21*C21 -> 0
A22: 19 | B22: 白葡萄酒 | C22: 98 | AX22: =SUM(D22:AW22) -> 0 | AY22: =AX22*C22 -> 0
A23: 20 | B23: 黄飞鸿 | C23: 38 | AX23: =SUM(D23:AW23) -> 0 | AY23: =AX23*C23 -> 0
A24: 21 | B24: 薯片 | C24: 58 | AX24: =SUM(D24:AW24) -> 0 | AY24: =AX24*C24 -> 0
C25: 总计个数 | D25: =SUM(D4:D24) -> 0 | E25: =SUM(E4:E24) -> 0 | F25: =SUM(F4:F24) -> 0 | G25: =SUM(G4:G24) -> 0 | H25: =SUM(H4:H24) -> 0 | I25: =SUM(I4:I24) -> 0 | J25: =SUM(J4:J24) -> 0 | K25: =SUM(K4:K24) -> 0 | ... AY25: =SUM(AY4:AY24) -> 0

Sheet 15
A1: 迷你吧入账单
A2: 序号 | B2: 品名 | C2: 房间号 单价 | Y2: 9500 | AX2: 总数 | AY2: 总金额
A4: 1 | B4: 圣培露 | C4: 60 | AX4: =SUM(D4:AW4) -> 0 | AY4: =AX4*C4 -> 0
A5: 2 | B5: 芙丝水 | C5: 60 | AX5: =SUM(D5:AW5) -> 0 | AY5: =AX5*C5 -> 0
A6: 3 | B6: 椰子水 | C6: 38 | AX6: =SUM(D6:AW6) -> 0 | AY6: =AX6*C6 -> 0
A7: 5 | B7: 梅子汁 | C7: 38 | AX7: =SUM(D7:AW7) -> 0 | AY7: =AX7*C7 -> 0
A8: 6 | B8: 百事可乐 | C8: 38 | AX8: =SUM(D8:AW8) -> 0 | AY8: =AX8*C8 -> 0
A9: 7 | B9: 健怡百事可乐 | C9: 38 | AX9: =SUM(D9:AW9) -> 0 | AY9: =AX9*C9 -> 0
A10: 8 | B10: 七喜 | C10: 38 | AX10: =SUM(D10:AW10) -> 0 | AY10: =AX10*C10 -> 0
A11: 9 | B11: 苏打水 | C11: 38 | AX11: =SUM(D11:AW11) -> 0 | AY11: =AX11*C11 -> 0
A12: 10 | B12: 汤力水 | C12: 38 | AX12: =SUM(D12:AW12) -> 0 | AY12: =AX12*C12 -> 0
AX13: =SUM(D13:AW13) -> 0 | AY13: =AX13*C13 -> 0
A14: 11 | B14: 必富达金酒 | C14: 58 | AX14: =SUM(D14:AW14) -> 0 | AY14: =AX14*C14 -> 0
A15: 12 | B15: 绝对伏特加 | C15: 58 | AX15: =SUM(D15:AW15) -> 0 | AY15: =AX15*C15 -> 0
A16: 13 | B16: 尊美醇威士忌 | C16: 58 | AX16: =SUM(D16:AW16) -> 0 | AY16: =AX16*C16 -> 0
A17: 14 | B17: 芝华士威士忌 | C17: 68 | AX17: =SUM(D17:AW17) -> 0 | AY17: =AX17*C17 -> 0
A18: 15 | B18: 马爹利名仕干邑 | C18: 108 | AX18: =SUM(D18:AW18) -> 0 | AY18: =AX18*C18 -> 0
A19: 16 | B19: 白熊啤酒 | C19: 68 | AX19: =SUM(D19:AW19) -> 0 | AY19: =AX19*C19 -> 0
A20: 17 | B20: 青岛啤酒 | C20: 38 | AX20: =SUM(D20:AW20) -> 0 | AY20: =AX20*C20 -> 0
A21: 18 | B21: 红葡萄酒 | C21: 98 | AX21: =SUM(D21:AW21) -> 0 | AY21: =AX21*C21 -> 0
A22: 19 | B22: 白葡萄酒 | C22: 98 | AX22: =SUM(D22:AW22) -> 0 | AY22: =AX22*C22 -> 0
A23: 20 | B23: 黄飞鸿 | C23: 38 | AX23: =SUM(D23:AW23) -> 0 | AY23: =AX23*C23 -> 0
A24: 21 | B24: 薯片 | C24: 58 | AX24: =SUM(D24:AW24) -> 0 | AY24: =AX24*C24 -> 0
C25: 总计个数 | D25: =SUM(D4:D24) -> 0 | E25: =SUM(E4:E24) -> 0 | F25: =SUM(F4:F24) -> 0 | G25: =SUM(G4:G24) -> 0 | H25: =SUM(H4:H24) -> 0 | I25: =SUM(I4:I24) -> 0 | J25: =SUM(J4:J24) -> 0 | K25: =SUM(K4:K24) -> 0 | ... AY25: =SUM(AY4:AY24) -> 0

Sheet 16
A1: 迷你吧入账单
A2: 序号 | B2: 品名 | C2: 房间号 单价 | Y2: 9500 | AX2: 总数 | AY2: 总金额
A4: 1 | B4: 圣培露 | C4: 60 | AX4: =SUM(D4:AW4) -> 0 | AY4: =AX4*C4 -> 0
A5: 2 | B5: 芙丝水 | C5: 60 | AX5: =SUM(D5:AW5) -> 0 | AY5: =AX5*C5 -> 0
A6: 3 | B6: 椰子水 | C6: 38 | AX6: =SUM(D6:AW6) -> 0 | AY6: =AX6*C6 -> 0
A7: 5 | B7: 梅子汁 | C7: 38 | AX7: =SUM(D7:AW7) -> 0 | AY7: =AX7*C7 -> 0
A8: 6 | B8: 百事可乐 | C8: 38 | AX8: =SUM(D8:AW8) -> 0 | AY8: =AX8*C8 -> 0
A9: 7 | B9: 健怡百事可乐 | C9: 38 | AX9: =SUM(D9:AW9) -> 0 | AY9: =AX9*C9 -> 0
A10: 8 | B10: 七喜 | C10: 38 | AX10: =SUM(D10:AW10) -> 0 | AY10: =AX10*C10 -> 0
A11: 9 | B11: 苏打水 | C11: 38 | AX11: =SUM(D11:AW11) -> 0 | AY11: =AX11*C11 -> 0
A12: 10 | B12: 汤力水 | C12: 38 | AX12: =SUM(D12:AW12) -> 0 | AY12: =AX12*C12 -> 0
AX13: =SUM(D13:AW13) -> 0 | AY13: =AX13*C13 -> 0
A14: 11 | B14: 必富达金酒 | C14: 58 | AX14: =SUM(D14:AW14) -> 0 | AY14: =AX14*C14 -> 0
A15: 12 | B15: 绝对伏特加 | C15: 58 | AX15: =SUM(D15:AW15) -> 0 | AY15: =AX15*C15 -> 0
A16: 13 | B16: 尊美醇威士忌 | C16: 58 | AX16: =SUM(D16:AW16) -> 0 | AY16: =AX16*C16 -> 0
A17: 14 | B17: 芝华士威士忌 | C17: 68 | AX17: =SUM(D17:AW17) -> 0 | AY17: =AX17*C17 -> 0
A18: 15 | B18: 马爹利名仕干邑 | C18: 108 | AX18: =SUM(D18:AW18) -> 0 | AY18: =AX18*C18 -> 0
A19: 16 | B19: 白熊啤酒 | C19: 68 | AX19: =SUM(D19:AW19) -> 0 | AY19: =AX19*C19 -> 0
A20: 17 | B20: 青岛啤酒 | C20: 38 | AX20: =SUM(D20:AW20) -> 0 | AY20: =AX20*C20 -> 0
A21: 18 | B21: 红葡萄酒 | C21: 98 | AX21: =SUM(D21:AW21) -> 0 | AY21: =AX21*C21 -> 0
A22: 19 | B22: 白葡萄酒 | C22: 98 | AX22: =SUM(D22:AW22) -> 0 | AY22: =AX22*C22 -> 0
A23: 20 | B23: 黄飞鸿 | C23: 38 | AX23: =SUM(D23:AW23) -> 0 | AY23: =AX23*C23 -> 0
A24: 21 | B24: 薯片 | C24: 58 | AX24: =SUM(D24:AW24) -> 0 | AY24: =AX24*C24 -> 0
C25: 总计个数 | D25: =SUM(D4:D24) -> 0 | E25: =SUM(E4:E24) -> 0 | F25: =SUM(F4:F24) -> 0 | G25: =SUM(G4:G24) -> 0 | H25: =SUM(H4:H24) -> 0 | I25: =SUM(I4:I24) -> 0 | J25: =SUM(J4:J24) -> 0 | K25: =SUM(K4:K24) -> 0 | ... AY25: =SUM(AY4:AY24) -> 0

Sheet 17
A1: 迷你吧入账单
A2: 序号 | B2: 品名 | C2: 房间号 单价 | Y2: 9500 | AX2: 总数 | AY2: 总金额
A4: 1 | B4: 圣培露 | C4: 60 | AX4: =SUM(D4:AW4) -> 0 | AY4: =AX4*C4 -> 0
A5: 2 | B5: 芙丝水 | C5: 60 | AX5: =SUM(D5:AW5) -> 0 | AY5: =AX5*C5 -> 0
A6: 3 | B6: 椰子水 | C6: 38 | AX6: =SUM(D6:AW6) -> 0 | AY6: =AX6*C6 -> 0
A7: 5 | B7: 梅子汁 | C7: 38 | AX7: =SUM(D7:AW7) -> 0 | AY7: =AX7*C7 -> 0
A8: 6 | B8: 百事可乐 | C8: 38 | AX8: =SUM(D8:AW8) -> 0 | AY8: =AX8*C8 -> 0
A9: 7 | B9: 健怡百事可乐 | C9: 38 | AX9: =SUM(D9:AW9) -> 0 | AY9: =AX9*C9 -> 0
A10: 8 | B10: 七喜 | C10: 38 | AX10: =SUM(D10:AW10) -> 0 | AY10: =AX10*C10 -> 0
A11: 9 | B11: 苏打水 | C11: 38 | AX11: =SUM(D11:AW11) -> 0 | AY11: =AX11*C11 -> 0
A12: 10 | B12: 汤力水 | C12: 38 | AX12: =SUM(D12:AW12) -> 0 | AY12: =AX12*C12 -> 0
AX13: =SUM(D13:AW13) -> 0 | AY13: =AX13*C13 -> 0
A14: 11 | B14: 必富达金酒 | C14: 58 | AX14: =SUM(D14:AW14) -> 0 | AY14: =AX14*C14 -> 0
A15: 12 | B15: 绝对伏特加 | C15: 58 | AX15: =SUM(D15:AW15) -> 0 | AY15: =AX15*C15 -> 0
A16: 13 | B16: 尊美醇威士忌 | C16: 58 | AX16: =SUM(D16:AW16) -> 0 | AY16: =AX16*C16 -> 0
A17: 14 | B17: 芝华士威士忌 | C17: 68 | AX17: =SUM(D17:AW17) -> 0 | AY17: =AX17*C17 -> 0
A18: 15 | B18: 马爹利名仕干邑 | C18: 108 | AX18: =SUM(D18:AW18) -> 0 | AY18: =AX18*C18 -> 0
A19: 16 | B19: 白熊啤酒 | C19: 68 | AX19: =SUM(D19:AW19) -> 0 | AY19: =AX19*C19 -> 0
A20: 17 | B20: 青岛啤酒 | C20: 38 | AX20: =SUM(D20:AW20) -> 0 | AY20: =AX20*C20 -> 0
A21: 18 | B21: 红葡萄酒 | C21: 98 | AX21: =SUM(D21:AW21) -> 0 | AY21: =AX21*C21 -> 0
A22: 19 | B22: 白葡萄酒 | C22: 98 | AX22: =SUM(D22:AW22) -> 0 | AY22: =AX22*C22 -> 0
A23: 20 | B23: 黄飞鸿 | C23: 38 | AX23: =SUM(D23:AW23) -> 0 | AY23: =AX23*C23 -> 0
A24: 21 | B24: 薯片 | C24: 58 | AX24: =SUM(D24:AW24) -> 0 | AY24: =AX24*C24 -> 0
C25: 总计个数 | D25: =SUM(D4:D24) -> 0 | E25: =SUM(E4:E24) -> 0 | F25: =SUM(F4:F24) -> 0 | G25: =SUM(G4:G24) -> 0 | H25: =SUM(H4:H24) -> 0 | I25: =SUM(I4:I24) -> 0 | J25: =SUM(J4:J24) -> 0 | K25: =SUM(K4:K24) -> 0 | ... AY25: =SUM(AY4:AY24) -> 0

Sheet 18
A1: 迷你吧入账单
A2: 序号 | B2: 品名 | C2: 房间号 单价 | Y2: 9500 | AX2: 总数 | AY2: 总金额
A4: 1 | B4: 圣培露 | C4: 60 | AX4: =SUM(D4:AW4) -> 0 | AY4: =AX4*C4 -> 0
A5: 2 | B5: 芙丝水 | C5: 60 | AX5: =SUM(D5:AW5) -> 0 | AY5: =AX5*C5 -> 0
A6: 3 | B6: 椰子水 | C6: 38 | AX6: =SUM(D6:AW6) -> 0 | AY6: =AX6*C6 -> 0
A7: 5 | B7: 梅子汁 | C7: 38 | AX7: =SUM(D7:AW7) -> 0 | AY7: =AX7*C7 -> 0
A8: 6 | B8: 百事可乐 | C8: 38 | AX8: =SUM(D8:AW8) -> 0 | AY8: =AX8*C8 -> 0
A9: 7 | B9: 健怡百事可乐 | C9: 38 | AX9: =SUM(D9:AW9) -> 0 | AY9: =AX9*C9 -> 0
A10: 8 | B10: 七喜 | C10: 38 | AX10: =SUM(D10:AW10) -> 0 | AY10: =AX10*C10 -> 0
A11: 9 | B11: 苏打水 | C11: 38 | AX11: =SUM(D11:AW11) -> 0 | AY11: =AX11*C11 -> 0
A12: 10 | B12: 汤力水 | C12: 38 | AX12: =SUM(D12:AW12) -> 0 | AY12: =AX12*C12 -> 0
AX13: =SUM(D13:AW13) -> 0 | AY13: =AX13*C13 -> 0
A14: 11 | B14: 必富达金酒 | C14: 58 | AX14: =SUM(D14:AW14) -> 0 | AY14: =AX14*C14 -> 0
A15: 12 | B15: 绝对伏特加 | C15: 58 | AX15: =SUM(D15:AW15) -> 0 | AY15: =AX15*C15 -> 0
A16: 13 | B16: 尊美醇威士忌 | C16: 58 | AX16: =SUM(D16:AW16) -> 0 | AY16: =AX16*C16 -> 0
A17: 14 | B17: 芝华士威士忌 | C17: 68 | AX17: =SUM(D17:AW17) -> 0 | AY17: =AX17*C17 -> 0
A18: 15 | B18: 马爹利名仕干邑 | C18: 108 | AX18: =SUM(D18:AW18) -> 0 | AY18: =AX18*C18 -> 0
A19: 16 | B19: 白熊啤酒 | C19: 68 | AX19: =SUM(D19:AW19) -> 0 | AY19: =AX19*C19 -> 0
A20: 17 | B20: 青岛啤酒 | C20: 38 | AX20: =SUM(D20:AW20) -> 0 | AY20: =AX20*C20 -> 0
A21: 18 | B21: 红葡萄酒 | C21: 98 | AX21: =SUM(D21:AW21) -> 0 | AY21: =AX21*C21 -> 0
A22: 19 | B22: 白葡萄酒 | C22: 98 | AX22: =SUM(D22:AW22) -> 0 | AY22: =AX22*C22 -> 0
A23: 20 | B23: 黄飞鸿 | C23: 38 | AX23: =SUM(D23:AW23) -> 0 | AY23: =AX23*C23 -> 0
A24: 21 | B24: 薯片 | C24: 58 | AX24: =SUM(D24:AW24) -> 0 | AY24: =AX24*C24 -> 0
C25: 总计个数 | D25: =SUM(D4:D24) -> 0 | E25: =SUM(E4:E24) -> 0 | F25: =SUM(F4:F24) -> 0 | G25: =SUM(G4:G24) -> 0 | H25: =SUM(H4:H24) -> 0 | I25: =SUM(I4:I24) -> 0 | J25: =SUM(J4:J24) -> 0 | K25: =SUM(K4:K24) -> 0 | ... AY25: =SUM(AY4:AY24) -> 0

Sheet 19
A1: 迷你吧入账单
A2: 序号 | B2: 品名 | C2: 房间号 单价 | Y2: 9500 | AX2: 总数 | AY2: 总金额
A4: 1 | B4: 圣培露 | C4: 60 | AX4: =SUM(D4:AW4) -> 0 | AY4: =AX4*C4 -> 0
A5: 2 | B5: 芙丝水 | C5: 60 | AX5: =SUM(D5:AW5) -> 0 | AY5: =AX5*C5 -> 0
A6: 3 | B6: 椰子水 | C6: 38 | AX6: =SUM(D6:AW6) -> 0 | AY6: =AX6*C6 -> 0
A7: 5 | B7: 梅子汁 | C7: 38 | AX7: =SUM(D7:AW7) -> 0 | AY7: =AX7*C7 -> 0
A8: 6 | B8: 百事可乐 | C8: 38 | AX8: =SUM(D8:AW8) -> 0 | AY8: =AX8*C8 -> 0
A9: 7 | B9: 健怡百事可乐 | C9: 38 | AX9: =SUM(D9:AW9) -> 0 | AY9: =AX9*C9 -> 0
A10: 8 | B10: 七喜 | C10: 38 | AX10: =SUM(D10:AW10) -> 0 | AY10: =AX10*C10 -> 0
A11: 9 | B11: 苏打水 | C11: 38 | AX11: =SUM(D11:AW11) -> 0 | AY11: =AX11*C11 -> 0
A12: 10 | B12: 汤力水 | C12: 38 | AX12: =SUM(D12:AW12) -> 0 | AY12: =AX12*C12 -> 0
AX13: =SUM(D13:AW13) -> 0 | AY13: =AX13*C13 -> 0
A14: 11 | B14: 必富达金酒 | C14: 58 | AX14: =SUM(D14:AW14) -> 0 | AY14: =AX14*C14 -> 0
A15: 12 | B15: 绝对伏特加 | C15: 58 | AX15: =SUM(D15:AW15) -> 0 | AY15: =AX15*C15 -> 0
A16: 13 | B16: 尊美醇威士忌 | C16: 58 | AX16: =SUM(D16:AW16) -> 0 | AY16: =AX16*C16 -> 0
A17: 14 | B17: 芝华士威士忌 | C17: 68 | AX17: =SUM(D17:AW17) -> 0 | AY17: =AX17*C17 -> 0
A18: 15 | B18: 马爹利名仕干邑 | C18: 108 | AX18: =SUM(D18:AW18) -> 0 | AY18: =AX18*C18 -> 0
A19: 16 | B19: 白熊啤酒 | C19: 68 | AX19: =SUM(D19:AW19) -> 0 | AY19: =AX19*C19 -> 0
A20: 17 | B20: 青岛啤酒 | C20: 38 | AX20: =SUM(D20:AW20) -> 0 | AY20: =AX20*C20 -> 0
A21: 18 | B21: 红葡萄酒 | C21: 98 | AX21: =SUM(D21:AW21) -> 0 | AY21: =AX21*C21 -> 0
A22: 19 | B22: 白葡萄酒 | C22: 98 | AX22: =SUM(D22:AW22) -> 0 | AY22: =AX22*C22 -> 0
A23: 20 | B23: 黄飞鸿 | C23: 38 | AX23: =SUM(D23:AW23) -> 0 | AY23: =AX23*C23 -> 0
A24: 21 | B24: 薯片 | C24: 58 | AX24: =SUM(D24:AW24) -> 0 | AY24: =AX24*C24 -> 0
C25: 总计个数 | D25: =SUM(D4:D24) -> 0 | E25: =SUM(E4:E24) -> 0 | F25: =SUM(F4:F24) -> 0 | G25: =SUM(G4:G24) -> 0 | H25: =SUM(H4:H24) -> 0 | I25: =SUM(I4:I24) -> 0 | J25: =SUM(J4:J24) -> 0 | K25: =SUM(K4:K24) -> 0 | ... AY25: =SUM(AY4:AY24) -> 0

Sheet 20
A1: 迷你吧入账单
A2: 序号 | B2: 品名 | C2: 房间号 单价 | Y2: 9500 | AX2: 总数 | AY2: 总金额
A4: 1 | B4: 圣培露 | C4: 60 | AX4: =SUM(D4:AW4) -> 0 | AY4: =AX4*C4 -> 0
A5: 2 | B5: 芙丝水 | C5: 60 | AX5: =SUM(D5:AW5) -> 0 | AY5: =AX5*C5 -> 0
A6: 3 | B6: 椰子水 | C6: 38 | AX6: =SUM(D6:AW6) -> 0 | AY6: =AX6*C6 -> 0
A7: 5 | B7: 梅子汁 | C7: 38 | AX7: =SUM(D7:AW7) -> 0 | AY7: =AX7*C7 -> 0
A8: 6 | B8: 百事可乐 | C8: 38 | AX8: =SUM(D8:AW8) -> 0 | AY8: =AX8*C8 -> 0
A9: 7 | B9: 健怡百事可乐 | C9: 38 | AX9: =SUM(D9:AW9) -> 0 | AY9: =AX9*C9 -> 0
A10: 8 | B10: 七喜 | C10: 38 | AX10: =SUM(D10:AW10) -> 0 | AY10: =AX10*C10 -> 0
A11: 9 | B11: 苏打水 | C11: 38 | AX11: =SUM(D11:AW11) -> 0 | AY11: =AX11*C11 -> 0
A12: 10 | B12: 汤力水 | C12: 38 | AX12: =SUM(D12:AW12) -> 0 | AY12: =AX12*C12 -> 0
AX13: =SUM(D13:AW13) -> 0 | AY13: =AX13*C13 -> 0
A14: 11 | B14: 必富达金酒 | C14: 58 | AX14: =SUM(D14:AW14) -> 0 | AY14: =AX14*C14 -> 0
A15: 12 | B15: 绝对伏特加 | C15: 58 | AX15: =SUM(D15:AW15) -> 0 | AY15: =AX15*C15 -> 0
A16: 13 | B16: 尊美醇威士忌 | C16: 58 | AX16: =SUM(D16:AW16) -> 0 | AY16: =AX16*C16 -> 0
A17: 14 | B17: 芝华士威士忌 | C17: 68 | AX17: =SUM(D17:AW17) -> 0 | AY17: =AX17*C17 -> 0
A18: 15 | B18: 马爹利名仕干邑 | C18: 108 | AX18: =SUM(D18:AW18) -> 0 | AY18: =AX18*C18 -> 0
A19: 16 | B19: 白熊啤酒 | C19: 68 | AX19: =SUM(D19:AW19) -> 0 | AY19: =AX19*C19 -> 0
A20: 17 | B20: 青岛啤酒 | C20: 38 | AX20: =SUM(D20:AW20) -> 0 | AY20: =AX20*C20 -> 0
A21: 18 | B21: 红葡萄酒 | C21: 98 | AX21: =SUM(D21:AW21) -> 0 | AY21: =AX21*C21 -> 0
A22: 19 | B22: 白葡萄酒 | C22: 98 | AX22: =SUM(D22:AW22) -> 0 | AY22: =AX22*C22 -> 0
A23: 20 | B23: 黄飞鸿 | C23: 38 | AX23: =SUM(D23:AW23) -> 0 | AY23: =AX23*C23 -> 0
A24: 21 | B24: 薯片 | C24: 58 | AX24: =SUM(D24:AW24) -> 0 | AY24: =AX24*C24 -> 0
C25: 总计个数 | D25: =SUM(D4:D24) -> 0 | E25: =SUM(E4:E24) -> 0 | F25: =SUM(F4:F24) -> 0 | G25: =SUM(G4:G24) -> 0 | H25: =SUM(H4:H24) -> 0 | I25: =SUM(I4:I24) -> 0 | J25: =SUM(J4:J24) -> 0 | K25: =SUM(K4:K24) -> 0 | ... AY25: =SUM(AY4:AY24) -> 0

Sheet 21
A1: 迷你吧入账单
A2: 序号 | B2: 品名 | C2: 房间号 单价 | Y2: 9500 | AX2: 总数 | AY2: 总金额
A4: 1 | B4: 圣培露 | C4: 60 | AX4: =SUM(D4:AW4) -> 0 | AY4: =AX4*C4 -> 0
A5: 2 | B5: 芙丝水 | C5: 60 | AX5: =SUM(D5:AW5) -> 0 | AY5: =AX5*C5 -> 0
A6: 3 | B6: 椰子水 | C6: 38 | AX6: =SUM(D6:AW6) -> 0 | AY6: =AX6*C6 -> 0
A7: 5 | B7: 梅子汁 | C7: 38 | AX7: =SUM(D7:AW7) -> 0 | AY7: =AX7*C7 -> 0
A8: 6 | B8: 百事可乐 | C8: 38 | AX8: =SUM(D8:AW8) -> 0 | AY8: =AX8*C8 -> 0
A9: 7 | B9: 健怡百事可乐 | C9: 38 | AX9: =SUM(D9:AW9) -> 0 | AY9: =AX9*C9 -> 0
A10: 8 | B10: 七喜 | C10: 38 | AX10: =SUM(D10:AW10) -> 0 | AY10: =AX10*C10 -> 0
A11: 9 | B11: 苏打水 | C11: 38 | AX11: =SUM(D11:AW11) -> 0 | AY11: =AX11*C11 -> 0
A12: 10 | B12: 汤力水 | C12: 38 | AX12: =SUM(D12:AW12) -> 0 | AY12: =AX12*C12 -> 0
AX13: =SUM(D13:AW13) -> 0 | AY13: =AX13*C13 -> 0
A14: 11 | B14: 必富达金酒 | C14: 58 | AX14: =SUM(D14:AW14) -> 0 | AY14: =AX14*C14 -> 0
A15: 12 | B15: 绝对伏特加 | C15: 58 | AX15: =SUM(D15:AW15) -> 0 | AY15: =AX15*C15 -> 0
A16: 13 | B16: 尊美醇威士忌 | C16: 58 | AX16: =SUM(D16:AW16) -> 0 | AY16: =AX16*C16 -> 0
A17: 14 | B17: 芝华士威士忌 | C17: 68 | AX17: =SUM(D17:AW17) -> 0 | AY17: =AX17*C17 -> 0
A18: 15 | B18: 马爹利名仕干邑 | C18: 108 | AX18: =SUM(D18:AW18) -> 0 | AY18: =AX18*C18 -> 0
A19: 16 | B19: 白熊啤酒 | C19: 68 | AX19: =SUM(D19:AW19) -> 0 | AY19: =AX19*C19 -> 0
A20: 17 | B20: 青岛啤酒 | C20: 38 | AX20: =SUM(D20:AW20) -> 0 | AY20: =AX20*C20 -> 0
A21: 18 | B21: 红葡萄酒 | C21: 98 | AX21: =SUM(D21:AW21) -> 0 | AY21: =AX21*C21 -> 0
A22: 19 | B22: 白葡萄酒 | C22: 98 | AX22: =SUM(D22:AW22) -> 0 | AY22: =AX22*C22 -> 0
A23: 20 | B23: 黄飞鸿 | C23: 38 | AX23: =SUM(D23:AW23) -> 0 | AY23: =AX23*C23 -> 0
A24: 21 | B24: 薯片 | C24: 58 | AX24: =SUM(D24:AW24) -> 0 | AY24: =AX24*C24 -> 0
C25: 总计个数 | D25: =SUM(D4:D24) -> 0 | E25: =SUM(E4:E24) -> 0 | F25: =SUM(F4:F24) -> 0 | G25: =SUM(G4:G24) -> 0 | H25: =SUM(H4:H24) -> 0 | I25: =SUM(I4:I24) -> 0 | J25: =SUM(J4:J24) -> 0 | K25: =SUM(K4:K24) -> 0 | ... AY25: =SUM(AY4:AY24) -> 0

Sheet 22
A1: 迷你吧入账单
A2: 序号 | B2: 品名 | C2: 房间号 单价 | Y2: 9500 | AX2: 总数 | AY2: 总金额
A4: 1 | B4: 圣培露 | C4: 60 | AX4: =SUM(D4:AW4) -> 0 | AY4: =AX4*C4 -> 0
A5: 2 | B5: 芙丝水 | C5: 60 | AX5: =SUM(D5:AW5) -> 0 | AY5: =AX5*C5 -> 0
A6: 3 | B6: 椰子水 | C6: 38 | AX6: =SUM(D6:AW6) -> 0 | AY6: =AX6*C6 -> 0
A7: 5 | B7: 梅子汁 | C7: 38 | AX7: =SUM(D7:AW7) -> 0 | AY7: =AX7*C7 -> 0
A8: 6 | B8: 百事可乐 | C8: 38 | AX8: =SUM(D8:AW8) -> 0 | AY8: =AX8*C8 -> 0
A9: 7 | B9: 健怡百事可乐 | C9: 38 | AX9: =SUM(D9:AW9) -> 0 | AY9: =AX9*C9 -> 0
A10: 8 | B10: 七喜 | C10: 38 | AX10: =SUM(D10:AW10) -> 0 | AY10: =AX10*C10 -> 0
A11: 9 | B11: 苏打水 | C11: 38 | AX11: =SUM(D11:AW11) -> 0 | AY11: =AX11*C11 -> 0
A12: 10 | B12: 汤力水 | C12: 38 | AX12: =SUM(D12:AW12) -> 0 | AY12: =AX12*C12 -> 0
AX13: =SUM(D13:AW13) -> 0 | AY13: =AX13*C13 -> 0
A14: 11 | B14: 必富达金酒 | C14: 58 | AX14: =SUM(D14:AW14) -> 0 | AY14: =AX14*C14 -> 0
A15: 12 | B15: 绝对伏特加 | C15: 58 | AX15: =SUM(D15:AW15) -> 0 | AY15: =AX15*C15 -> 0
A16: 13 | B16: 尊美醇威士忌 | C16: 58 | AX16: =SUM(D16:AW16) -> 0 | AY16: =AX16*C16 -> 0
A17: 14 | B17: 芝华士威士忌 | C17: 68 | AX17: =SUM(D17:AW17) -> 0 | AY17: =AX17*C17 -> 0
A18: 15 | B18: 马爹利名仕干邑 | C18: 108 | AX18: =SUM(D18:AW18) -> 0 | AY18: =AX18*C18 -> 0
A19: 16 | B19: 白熊啤酒 | C19: 68 | AX19: =SUM(D19:AW19) -> 0 | AY19: =AX19*C19 -> 0
A20: 17 | B20: 青岛啤酒 | C20: 38 | AX20: =SUM(D20:AW20) -> 0 | AY20: =AX20*C20 -> 0
A21: 18 | B21: 红葡萄酒 | C21: 98 | AX21: =SUM(D21:AW21) -> 0 | AY21: =AX21*C21 -> 0
A22: 19 | B22: 白葡萄酒 | C22: 98 | AX22: =SUM(D22:AW22) -> 0 | AY22: =AX22*C22 -> 0
A23: 20 | B23: 黄飞鸿 | C23: 38 | AX23: =SUM(D23:AW23) -> 0 | AY23: =AX23*C23 -> 0
A24: 21 | B24: 薯片 | C24: 58 | AX24: =SUM(D24:AW24) -> 0 | AY24: =AX24*C24 -> 0
C25: 总计个数 | D25: =SUM(D4:D24) -> 0 | E25: =SUM(E4:E24) -> 0 | F25: =SUM(F4:F24) -> 0 | G25: =SUM(G4:G24) -> 0 | H25: =SUM(H4:H24) -> 0 | I25: =SUM(I4:I24) -> 0 | J25: =SUM(J4:J24) -> 0 | K25: =SUM(K4:K24) -> 0 | ... AY25: =SUM(AY4:AY24) -> 0

Sheet 23
A1: 迷你吧入账单
A2: 序号 | B2: 品名 | C2: 房间号 单价 | Y2: 9500 | AX2: 总数 | AY2: 总金额
A4: 1 | B4: 圣培露 | C4: 60 | AX4: =SUM(D4:AW4) -> 0 | AY4: =AX4*C4 -> 0
A5: 2 | B5: 芙丝水 | C5: 60 | AX5: =SUM(D5:AW5) -> 0 | AY5: =AX5*C5 -> 0
A6: 3 | B6: 椰子水 | C6: 38 | AX6: =SUM(D6:AW6) -> 0 | AY6: =AX6*C6 -> 0
A7: 5 | B7: 梅子汁 | C7: 38 | AX7: =SUM(D7:AW7) -> 0 | AY7: =AX7*C7 -> 0
A8: 6 | B8: 百事可乐 | C8: 38 | AX8: =SUM(D8:AW8) -> 0 | AY8: =AX8*C8 -> 0
A9: 7 | B9: 健怡百事可乐 | C9: 38 | AX9: =SUM(D9:AW9) -> 0 | AY9: =AX9*C9 -> 0
A10: 8 | B10: 七喜 | C10: 38 | AX10: =SUM(D10:AW10) -> 0 | AY10: =AX10*C10 -> 0
A11: 9 | B11: 苏打水 | C11: 38 | AX11: =SUM(D11:AW11) -> 0 | AY11: =AX11*C11 -> 0
A12: 10 | B12: 汤力水 | C12: 38 | AX12: =SUM(D12:AW12) -> 0 | AY12: =AX12*C12 -> 0
AX13: =SUM(D13:AW13) -> 0 | AY13: =AX13*C13 -> 0
A14: 11 | B14: 必富达金酒 | C14: 58 | AX14: =SUM(D14:AW14) -> 0 | AY14: =AX14*C14 -> 0
A15: 12 | B15: 绝对伏特加 | C15: 58 | AX15: =SUM(D15:AW15) -> 0 | AY15: =AX15*C15 -> 0
A16: 13 | B16: 尊美醇威士忌 | C16: 58 | AX16: =SUM(D16:AW16) -> 0 | AY16: =AX16*C16 -> 0
A17: 14 | B17: 芝华士威士忌 | C17: 68 | AX17: =SUM(D17:AW17) -> 0 | AY17: =AX17*C17 -> 0
A18: 15 | B18: 马爹利名仕干邑 | C18: 108 | AX18: =SUM(D18:AW18) -> 0 | AY18: =AX18*C18 -> 0
